{
 "cells": [
  {
   "cell_type": "markdown",
   "metadata": {},
   "source": [
    "# Getting Started with Echodataflow: Processing EK60 Data to Extract Target Strength\n",
    "\n",
    "Welcome to this beginner-friendly notebook that guides you through the process of using `echodataflow` to process EK60 data from the SH1707 survey. `echodataflow` is a powerful tool for ocean acoustics data processing. In this notebook, we'll walk through the following steps:\n",
    "\n",
    "1. **Setting Up**: Importing necessary libraries and setting up the configuration paths for the dataset and pipeline.\n",
    "\n",
    "2. **Getting Data**: Using `glob_url` to retrieve a list of URLs matching the specified pattern of raw EK60 data files.\n",
    "\n",
    "3. **Preparing Files**: Extracting file names from URLs and creating a file listing for the transect.\n",
    "\n",
    "4. **Processing with echodataflow**: Starting the echodataflow processing using the specified configurations.\n",
    "\n",
    "5. **Results**: Displaying the first entry from the processed data.\n",
    "\n",
    "Let's get started!"
   ]
  },
  {
   "cell_type": "markdown",
   "metadata": {},
   "source": [
    "# Step 0: Install Echodataflow\n",
    "\n",
    "Before we proceed with the instructions on using `echodataflow`, let's ensure that we have properly set up and prepared our system with echodataflow for usage. Feel free to skip this step if you have echodataflow already set up.\n",
    "\n",
    "### Step 0.1: Make a virtual environment\n",
    "\n",
    "To keep your Echodataflow environment isolated, it's recommended to create a virtual environment using Conda or Python's built-in venv module. Here's an example using Conda:\n",
    "\n",
    "```bash\n",
    "conda create --name echodataflow-env\n",
    "conda activate echodataflow-env\n",
    "```\n",
    "\n",
    "Or, using Python's venv:\n",
    "\n",
    "```bash\n",
    "python -m venv echodataflow-env\n",
    "source echodataflow-env/bin/activate  # On Windows, use `echodataflow-env\\Scripts\\activate`\n",
    "```\n",
    "### Step 0.2: Clone the Repository\n",
    "Now that you have a virtual environment set up, you can clone the Echodataflow project repository to your local machine using the following command:\n",
    "\n",
    "```bash\n",
    "git clone <echodataflow_repo>\n",
    "```\n",
    "\n",
    "### Step 0.3: Install the Package\n",
    "Navigate to the project directory you've just cloned and install the Echodataflow package. The -e flag is crucial as it enables editable mode, which is especially helpful during development and testing. Now, take a moment and let the echodataflow do its thing while you enjoy your coffee.\n",
    "\n",
    "```bash\n",
    "cd <project_directory>\n",
    "pip install -e .\n",
    "```\n",
    "\n",
    "---\n",
    "\n",
    "### Step 0.4: Initialize Echodataflow and Prefect\n",
    "\n",
    "To kickstart your journey with Echodataflow and Prefect, follow these simple initialization steps:\n",
    "\n",
    "##### 0.4.1 Initializing Echodataflow\n",
    "Begin by initializing Echodataflow with the following command:\n",
    "\n",
    "```bash\n",
    "echodataflow init\n",
    "```\n",
    "\n",
    "This command sets up the groundwork for your Echodataflow environment, preparing it for seamless usage.\n",
    "\n",
    "##### 0.4.2 Initializing Prefect\n",
    "For Prefect, initialization involves a few extra steps, including secure authentication. Enter the following command to initiate the Prefect authentication process:\n",
    "\n",
    "- If you have a Prefect Cloud account, provide your Prefect API key to securely link your account. Type your API key when prompted and press Enter.\n",
    "\n",
    "```bash\n",
    "prefect cloud login\n",
    "```\n",
    "\n",
    "- If you don't have a Prefect Cloud account yet, you can use local prefect account. This is especially useful for those who are just starting out and want to explore Prefect without an account.\n",
    "\n",
    "```bash\n",
    "prefect profiles create echodataflow-local\n",
    "```\n",
    "\n",
    "\n",
    "The initialization process will ensure that both Echodataflow and Prefect are properly set up and ready for you to dive into your cloud-based workflows.\n",
    "\n",
    "---"
   ]
  },
  {
   "cell_type": "markdown",
   "metadata": {},
   "source": [
    "## Step 1: Setting Up\n",
    "\n",
    "We begin by importing the required libraries and specifying the paths for the dataset and pipeline configuration files. These files contain the necessary information for data processing."
   ]
  },
  {
   "cell_type": "code",
   "execution_count": 1,
   "metadata": {},
   "outputs": [],
   "source": [
    "from pathlib import Path\n",
    "from echodataflow import echodataflow_start, glob_url\n",
    "\n",
    "dataset_config = Path(\"./datastore.yaml\").resolve()\n",
    "pipeline_config = Path(\"./pipeline.yaml\").resolve()"
   ]
  },
  {
   "cell_type": "markdown",
   "metadata": {},
   "source": [
    "## Step 1.1\n",
    "### Pipeline Configuration: Target Strength Processing\n",
    "In this section, we will provide you with the pipeline configuration that we'll be using for our target strength processing. The configuration is presented in YAML format, which is a structured and human-readable way to define settings for data processing.\n",
    "\n",
    "Here's the configuration we'll be using:\n",
    "\n",
    "```yaml\n",
    "active_recipe: target_strength \n",
    "use_local_dask: true\n",
    "n_workers: 5\n",
    "pipeline:\n",
    "- recipe_name: target_strength\n",
    "  stages:\n",
    "  - name: echodataflow_open_raw\n",
    "    module: echodataflow.stages.subflows.open_raw\n",
    "    options:\n",
    "      save_raw_file: true\n",
    "      use_raw_offline: true\n",
    "      use_offline: true\n",
    "  - name: echodataflow_compute_TS\n",
    "    module: echodataflow.stages.subflows.compute_TS\n",
    "    options:\n",
    "      use_offline: true\n",
    "```\n",
    "\n",
    "Let's break down the components of this configuration:\n",
    "\n",
    "- **active_recipe**: Specifies the recipe to be used for processing, which is set as \"target_strength\" in this case.\n",
    "\n",
    "- **use_local_dask**: This flag indicates that we'll be utilizing a local Dask Cluster for parallel processing.\n",
    "\n",
    "- **n_workers**: Determines the number of worker processes in the Dask Cluster. Here, we're using 5 workers for efficient parallelization.\n",
    "\n",
    "- **pipeline**: This section defines the sequence of stages to execute. In this example, we're following the \"target_strength\" recipe, which comprises two stages.\n",
    "\n",
    "- **echodataflow_open_raw**: This stage utilizes the `open_raw` subflow module to open raw data files. It includes options such as saving raw files, using raw data in offline mode, and utilizing offline data.\n",
    "\n",
    "- **echodataflow_compute_TS**: This stage employs the `compute_TS` subflow module to compute target strength. It includes an option to use offline data.\n",
    "\n",
    "**Note**: For a more comprehensive understanding of each option and its functionality, you can refer to the [Pipeline documentation](https://github.com/OSOceanAcoustics/echodataflow/blob/dev/docs/configuration/pipeline.md).\n",
    "\n",
    "Keep in mind that in this example, we'll be setting up a local Dask Cluster with 5 workers for parallel processing. This configuration will enable us to efficiently process our data for target strength analysis. To turn it off, toggle `use_local_dask` to false.\n",
    "\n",
    "Feel free to explore and modify the configuration to understand better."
   ]
  },
  {
   "cell_type": "markdown",
   "metadata": {},
   "source": [
    "## Step 1.2\n",
    "### Datastore Configuration: Organizing Data for Processing\n",
    "\n",
    "In this section, we'll delve into the configuration that defines how the data will be organized and managed for processing. This configuration is provided in YAML format and plays a crucial role in structuring data inputs and outputs.\n",
    "\n",
    "Here's the detailed breakdown of the configuration:\n",
    "\n",
    "```yaml\n",
    "name: Bell_M._Shimada-SH1707-EK60\n",
    "sonar_model: EK60 \n",
    "raw_regex: (.*)-?D(?P<date>\\w{1,8})-T(?P<time>\\w{1,6}) \n",
    "args: \n",
    "  urlpath: s3://ncei-wcsd-archive/data/raw/{{ ship_name }}/{{ survey_name }}/{{ sonar_model }}/*.raw\n",
    "  parameters:\n",
    "    ship_name: Bell_M._Shimada\n",
    "    survey_name: SH1707\n",
    "    sonar_model: EK60\n",
    "  storage_options:\n",
    "    anon: true\n",
    "  transect:\n",
    "    file: ./EK60_SH1707_Shimada.txt\n",
    "  default_transect_num: 2017\n",
    "  json_export: true \n",
    "output: \n",
    "  urlpath: ./echodataflow-output\n",
    "  retention: false\n",
    "  overwrite: true\n",
    "```\n",
    "\n",
    "Let's delve into the individual components of the configuration presented here:\n",
    "\n",
    "- **name**: Specifies a descriptive name for the configuration, aiding in identifying its purpose.\n",
    "\n",
    "- **sonar_model**: Indicates the type of sonar being utilized, which in this case is \"EK60\".\n",
    "\n",
    "- **raw_regex**: Defines a regular expression pattern for extracting date and time information from raw data file names.\n",
    "\n",
    "- **args**: This section provides crucial arguments for structuring data inputs:\n",
    "\n",
    "  - **urlpath**: Defines the URL pattern to access the raw data files stored on a remote server. The placeholders `{{ ship_name }}`, `{{ survey_name }}`, and `{{ sonar_model }}` are dynamically replaced with the specified values.\n",
    "\n",
    "  - **storage_options**: Sets storage options, such as anonymous access (`anon: true`), for retrieving the data.\n",
    "\n",
    "  - **transect**: Specifies a file (`EK60_SH1707_Shimada.txt`) containing the list of files to process, along with default transect information.\n",
    "\n",
    "  - **json_export**: Enables JSON metadata export.\n",
    "\n",
    "- **output**: This section configures the output settings for processed data:\n",
    "\n",
    "  - **urlpath**: Determines the output directory (`./echodataflow-output`) where the processed data will be stored.\n",
    "\n",
    "  - **retention**: Disables data retention, indicating that only Target Strength data will be stored in this case.\n",
    "\n",
    "  - **overwrite**: Allows data overwriting if the data already exists.\n",
    "\n",
    "**Note**: \n",
    "- For a more comprehensive understanding of each option and its functionality, you can refer to the [Datast documentation](https://github.com/OSOceanAcoustics/echodataflow/blob/dev/docs/configuration/datastore.md).\n",
    "- The pipeline will store Target Strength output under `./echodataflow-output`. As the retention is set to false, only Target Strength files will be stored. To specify files for processing, create a list of file names and store it in `EK60_SH1707_Shimada.txt`, which should be placed under the transect directory.\n",
    "\n",
    "This configuration facilitates efficient data organization and management for the processing pipeline. Feel free to tailor it to your specific data and processing requirements.\n"
   ]
  },
  {
   "cell_type": "markdown",
   "metadata": {},
   "source": [
    "## Step 2: Getting Data\n",
    "Next, we'll use the glob_url function to retrieve a list of URLs matching a specific pattern. In this case, we're targeting raw EK60 data files from the SH1707 survey."
   ]
  },
  {
   "cell_type": "code",
   "execution_count": 2,
   "metadata": {},
   "outputs": [],
   "source": [
    "all_files = glob_url(\"s3://ncei-wcsd-archive/data/raw/Bell_M._Shimada/SH1707/EK60/*.raw\", {'anon':True})"
   ]
  },
  {
   "cell_type": "markdown",
   "metadata": {},
   "source": [
    "## Step 3: Preparing Files\n",
    "We'll now extract the file names from the URLs and create a file listing for the transect. This will help us organize and work with the data effectively."
   ]
  },
  {
   "cell_type": "code",
   "execution_count": 3,
   "metadata": {},
   "outputs": [],
   "source": [
    "files = []\n",
    "for file in all_files:\n",
    "    f = file.split(\".r\")[0]\n",
    "    files.append(f.split(\"/\")[-1])\n",
    "\n",
    "transect = open('EK60_SH1707_Shimada.txt','w')\n",
    "i = 0\n",
    "for f in files:\n",
    "    if i == 10:\n",
    "        break\n",
    "    transect.write(f+\".raw\\n\")\n",
    "    i = i + 1\n",
    "transect.close()"
   ]
  },
  {
   "cell_type": "markdown",
   "metadata": {},
   "source": [
    "## Step 4: Processing with echodataflow\n",
    "Now, we're ready to kick off the data processing using echodataflow. We'll provide the dataset and pipeline configurations, along with additional options."
   ]
  },
  {
   "cell_type": "code",
   "execution_count": 4,
   "metadata": {},
   "outputs": [
    {
     "name": "stdout",
     "output_type": "stream",
     "text": [
      "\n",
      "Checking Configuration\n",
      "\n",
      "Configuration Check Completed\n",
      "Checking Connection to Prefect Server\n",
      "\n",
      "Starting the Pipeline\n",
      "\n",
      "\n",
      "Dataset Configuration Loaded For This Run\n",
      "--------------------------------------------------\n",
      "{'name': 'Bell_M._Shimada-SH1707-EK60', 'sonar_model': 'EK60', 'raw_regex': '(.*)-?D(?P<date>\\\\w{1,8})-T(?P<time>\\\\w{1,6})', 'args': {'urlpath': 's3://ncei-wcsd-archive/data/raw/{{ ship_name }}/{{ survey_name }}/{{ sonar_model }}/*.raw', 'parameters': {'ship_name': 'Bell_M._Shimada', 'survey_name': 'SH1707', 'sonar_model': 'EK60'}, 'storage_options': {'anon': True}, 'transect': {'file': './EK60_SH1707_Shimada.txt'}, 'default_transect_num': 2017, 'json_export': True}, 'output': {'urlpath': './echodataflow-output', 'retention': True, 'overwrite': True}}\n",
      "Pipeline Configuration Loaded For This Run\n",
      "--------------------------------------------------\n",
      "{'active_recipe': 'target_strength', 'use_local_dask': False, 'n_workers': 5, 'pipeline': [{'recipe_name': 'target_strength', 'stages': [{'name': 'echodataflow_open_raw', 'module': 'echodataflow.stages.subflows.open_raw', 'options': {'save_raw_file': True, 'use_raw_offline': True, 'use_offline': True}}, {'name': 'echodataflow_compute_TS', 'module': 'echodataflow.stages.subflows.compute_TS', 'options': {'use_offline': True}}]}]}\n",
      "\n",
      "Initiliazing Singleton Object\n",
      "\n",
      "Reading Configutations\n",
      "[]\n",
      "[]\n"
     ]
    },
    {
     "data": {
      "text/html": [
       "<pre style=\"white-space:pre;overflow-x:auto;line-height:normal;font-family:Menlo,'DejaVu Sans Mono',consolas,'Courier New',monospace\">20:16:16.235 | <span style=\"color: #d70000; text-decoration-color: #d70000\">ERROR</span>   | Task run 'club_raw_files-0' - Encountered exception during execution:\n",
       "Traceback (most recent call last):\n",
       "  File \"c:\\Users\\soham\\anaconda3\\envs\\echodataflow\\lib\\site-packages\\prefect\\engine.py\", line 1760, in orchestrate_task_run\n",
       "    result = await call.aresult()\n",
       "  File \"c:\\Users\\soham\\anaconda3\\envs\\echodataflow\\lib\\site-packages\\prefect\\_internal\\concurrency\\calls.py\", line 293, in aresult\n",
       "    return await asyncio.wrap_future(self.future)\n",
       "  File \"c:\\Users\\soham\\anaconda3\\envs\\echodataflow\\lib\\asyncio\\futures.py\", line 285, in __await__\n",
       "    yield self  # This tells Task to wait for completion.\n",
       "  File \"c:\\Users\\soham\\anaconda3\\envs\\echodataflow\\lib\\asyncio\\tasks.py\", line 304, in __wakeup\n",
       "    future.result()\n",
       "  File \"c:\\Users\\soham\\anaconda3\\envs\\echodataflow\\lib\\asyncio\\futures.py\", line 201, in result\n",
       "    raise self._exception.with_traceback(self._exception_tb)\n",
       "  File \"c:\\Users\\soham\\anaconda3\\envs\\echodataflow\\lib\\site-packages\\prefect\\_internal\\concurrency\\calls.py\", line 318, in _run_sync\n",
       "    result = self.fn(*self.args, **self.kwargs)\n",
       "  File \"c:\\Users\\soham\\anaconda3\\envs\\echodataflow\\lib\\site-packages\\echodataflow\\aspects\\echodataflow_aspect.py\", line 97, in wrapper\n",
       "    raise e\n",
       "  File \"c:\\Users\\soham\\anaconda3\\envs\\echodataflow\\lib\\site-packages\\echodataflow\\aspects\\echodataflow_aspect.py\", line 90, in wrapper\n",
       "    result = func(*args, **kwargs)\n",
       "  File \"c:\\Users\\soham\\anaconda3\\envs\\echodataflow\\lib\\site-packages\\echodataflow\\utils\\config_utils.py\", line 440, in club_raw_files\n",
       "    raise ValueError(\"Must have raw_dicts or raw_json_path present.\")\n",
       "ValueError: Must have raw_dicts or raw_json_path present.\n",
       "</pre>\n"
      ],
      "text/plain": [
       "20:16:16.235 | \u001b[38;5;160mERROR\u001b[0m   | Task run 'club_raw_files-0' - Encountered exception during execution:\n",
       "Traceback (most recent call last):\n",
       "  File \"c:\\Users\\soham\\anaconda3\\envs\\echodataflow\\lib\\site-packages\\prefect\\engine.py\", line 1760, in orchestrate_task_run\n",
       "    result = await call.aresult()\n",
       "  File \"c:\\Users\\soham\\anaconda3\\envs\\echodataflow\\lib\\site-packages\\prefect\\_internal\\concurrency\\calls.py\", line 293, in aresult\n",
       "    return await asyncio.wrap_future(self.future)\n",
       "  File \"c:\\Users\\soham\\anaconda3\\envs\\echodataflow\\lib\\asyncio\\futures.py\", line 285, in __await__\n",
       "    yield self  # This tells Task to wait for completion.\n",
       "  File \"c:\\Users\\soham\\anaconda3\\envs\\echodataflow\\lib\\asyncio\\tasks.py\", line 304, in __wakeup\n",
       "    future.result()\n",
       "  File \"c:\\Users\\soham\\anaconda3\\envs\\echodataflow\\lib\\asyncio\\futures.py\", line 201, in result\n",
       "    raise self._exception.with_traceback(self._exception_tb)\n",
       "  File \"c:\\Users\\soham\\anaconda3\\envs\\echodataflow\\lib\\site-packages\\prefect\\_internal\\concurrency\\calls.py\", line 318, in _run_sync\n",
       "    result = self.fn(*self.args, **self.kwargs)\n",
       "  File \"c:\\Users\\soham\\anaconda3\\envs\\echodataflow\\lib\\site-packages\\echodataflow\\aspects\\echodataflow_aspect.py\", line 97, in wrapper\n",
       "    raise e\n",
       "  File \"c:\\Users\\soham\\anaconda3\\envs\\echodataflow\\lib\\site-packages\\echodataflow\\aspects\\echodataflow_aspect.py\", line 90, in wrapper\n",
       "    result = func(*args, **kwargs)\n",
       "  File \"c:\\Users\\soham\\anaconda3\\envs\\echodataflow\\lib\\site-packages\\echodataflow\\utils\\config_utils.py\", line 440, in club_raw_files\n",
       "    raise ValueError(\"Must have raw_dicts or raw_json_path present.\")\n",
       "ValueError: Must have raw_dicts or raw_json_path present.\n"
      ]
     },
     "metadata": {},
     "output_type": "display_data"
    },
    {
     "data": {
      "text/html": [
       "<pre style=\"white-space:pre;overflow-x:auto;line-height:normal;font-family:Menlo,'DejaVu Sans Mono',consolas,'Courier New',monospace\">20:16:16.303 | <span style=\"color: #d70000; text-decoration-color: #d70000\">ERROR</span>   | Task run 'club_raw_files-0' - Finished in state <span style=\"color: #d70000; text-decoration-color: #d70000\">Failed</span>('Task run encountered an exception ValueError: Must have raw_dicts or raw_json_path present.')\n",
       "</pre>\n"
      ],
      "text/plain": [
       "20:16:16.303 | \u001b[38;5;160mERROR\u001b[0m   | Task run 'club_raw_files-0' - Finished in state \u001b[38;5;160mFailed\u001b[0m('Task run encountered an exception ValueError: Must have raw_dicts or raw_json_path present.')\n"
      ]
     },
     "metadata": {},
     "output_type": "display_data"
    },
    {
     "data": {
      "text/html": [
       "<pre style=\"white-space:pre;overflow-x:auto;line-height:normal;font-family:Menlo,'DejaVu Sans Mono',consolas,'Courier New',monospace\">20:16:16.306 | <span style=\"color: #d70000; text-decoration-color: #d70000\">ERROR</span>   | Flow run<span style=\"color: #800080; text-decoration-color: #800080\"> 'incredible-capuchin'</span> - Encountered exception during execution:\n",
       "Traceback (most recent call last):\n",
       "  File \"c:\\Users\\soham\\anaconda3\\envs\\echodataflow\\lib\\site-packages\\prefect\\engine.py\", line 841, in orchestrate_flow_run\n",
       "    result = await flow_call.aresult()\n",
       "  File \"c:\\Users\\soham\\anaconda3\\envs\\echodataflow\\lib\\site-packages\\prefect\\_internal\\concurrency\\calls.py\", line 293, in aresult\n",
       "    return await asyncio.wrap_future(self.future)\n",
       "  File \"c:\\Users\\soham\\anaconda3\\envs\\echodataflow\\lib\\asyncio\\futures.py\", line 285, in __await__\n",
       "    yield self  # This tells Task to wait for completion.\n",
       "  File \"c:\\Users\\soham\\anaconda3\\envs\\echodataflow\\lib\\asyncio\\tasks.py\", line 304, in __wakeup\n",
       "    future.result()\n",
       "  File \"c:\\Users\\soham\\anaconda3\\envs\\echodataflow\\lib\\asyncio\\futures.py\", line 201, in result\n",
       "    raise self._exception.with_traceback(self._exception_tb)\n",
       "  File \"c:\\Users\\soham\\anaconda3\\envs\\echodataflow\\lib\\site-packages\\prefect\\_internal\\concurrency\\calls.py\", line 318, in _run_sync\n",
       "    result = self.fn(*self.args, **self.kwargs)\n",
       "  File \"c:\\Users\\soham\\anaconda3\\envs\\echodataflow\\lib\\site-packages\\echodataflow\\aspects\\echodataflow_aspect.py\", line 97, in wrapper\n",
       "    raise e\n",
       "  File \"c:\\Users\\soham\\anaconda3\\envs\\echodataflow\\lib\\site-packages\\echodataflow\\aspects\\echodataflow_aspect.py\", line 90, in wrapper\n",
       "    result = func(*args, **kwargs)\n",
       "  File \"c:\\Users\\soham\\anaconda3\\envs\\echodataflow\\lib\\site-packages\\echodataflow\\stages\\subflows\\initialization_flow.py\", line 74, in init_flow\n",
       "    data = club_raw_files(\n",
       "  File \"c:\\Users\\soham\\anaconda3\\envs\\echodataflow\\lib\\site-packages\\prefect\\tasks.py\", line 549, in __call__\n",
       "    return enter_task_run_engine(\n",
       "  File \"c:\\Users\\soham\\anaconda3\\envs\\echodataflow\\lib\\site-packages\\prefect\\engine.py\", line 1156, in enter_task_run_engine\n",
       "    return from_sync.wait_for_call_in_loop_thread(begin_run)\n",
       "  File \"c:\\Users\\soham\\anaconda3\\envs\\echodataflow\\lib\\site-packages\\prefect\\_internal\\concurrency\\api.py\", line 243, in wait_for_call_in_loop_thread\n",
       "    return call.result()\n",
       "  File \"c:\\Users\\soham\\anaconda3\\envs\\echodataflow\\lib\\site-packages\\prefect\\_internal\\concurrency\\calls.py\", line 284, in result\n",
       "    return self.future.result(timeout=timeout)\n",
       "  File \"c:\\Users\\soham\\anaconda3\\envs\\echodataflow\\lib\\site-packages\\prefect\\_internal\\concurrency\\calls.py\", line 168, in result\n",
       "    return self.__get_result()\n",
       "  File \"c:\\Users\\soham\\anaconda3\\envs\\echodataflow\\lib\\concurrent\\futures\\_base.py\", line 403, in __get_result\n",
       "    raise self._exception\n",
       "  File \"c:\\Users\\soham\\anaconda3\\envs\\echodataflow\\lib\\site-packages\\prefect\\_internal\\concurrency\\calls.py\", line 355, in _run_async\n",
       "    result = await coro\n",
       "  File \"c:\\Users\\soham\\anaconda3\\envs\\echodataflow\\lib\\site-packages\\prefect\\engine.py\", line 1324, in get_task_call_return_value\n",
       "    return await future._result()\n",
       "  File \"c:\\Users\\soham\\anaconda3\\envs\\echodataflow\\lib\\site-packages\\prefect\\futures.py\", line 237, in _result\n",
       "    return await final_state.result(raise_on_failure=raise_on_failure, fetch=True)\n",
       "  File \"c:\\Users\\soham\\anaconda3\\envs\\echodataflow\\lib\\site-packages\\prefect\\states.py\", line 91, in _get_state_result\n",
       "    raise await get_state_exception(state)\n",
       "  File \"c:\\Users\\soham\\anaconda3\\envs\\echodataflow\\lib\\site-packages\\prefect\\engine.py\", line 1760, in orchestrate_task_run\n",
       "    result = await call.aresult()\n",
       "  File \"c:\\Users\\soham\\anaconda3\\envs\\echodataflow\\lib\\site-packages\\prefect\\_internal\\concurrency\\calls.py\", line 293, in aresult\n",
       "    return await asyncio.wrap_future(self.future)\n",
       "  File \"c:\\Users\\soham\\anaconda3\\envs\\echodataflow\\lib\\asyncio\\futures.py\", line 285, in __await__\n",
       "    yield self  # This tells Task to wait for completion.\n",
       "  File \"c:\\Users\\soham\\anaconda3\\envs\\echodataflow\\lib\\asyncio\\tasks.py\", line 304, in __wakeup\n",
       "    future.result()\n",
       "  File \"c:\\Users\\soham\\anaconda3\\envs\\echodataflow\\lib\\asyncio\\futures.py\", line 201, in result\n",
       "    raise self._exception.with_traceback(self._exception_tb)\n",
       "  File \"c:\\Users\\soham\\anaconda3\\envs\\echodataflow\\lib\\site-packages\\prefect\\_internal\\concurrency\\calls.py\", line 318, in _run_sync\n",
       "    result = self.fn(*self.args, **self.kwargs)\n",
       "  File \"c:\\Users\\soham\\anaconda3\\envs\\echodataflow\\lib\\site-packages\\echodataflow\\aspects\\echodataflow_aspect.py\", line 97, in wrapper\n",
       "    raise e\n",
       "  File \"c:\\Users\\soham\\anaconda3\\envs\\echodataflow\\lib\\site-packages\\echodataflow\\aspects\\echodataflow_aspect.py\", line 90, in wrapper\n",
       "    result = func(*args, **kwargs)\n",
       "  File \"c:\\Users\\soham\\anaconda3\\envs\\echodataflow\\lib\\site-packages\\echodataflow\\utils\\config_utils.py\", line 440, in club_raw_files\n",
       "    raise ValueError(\"Must have raw_dicts or raw_json_path present.\")\n",
       "ValueError: Must have raw_dicts or raw_json_path present.\n",
       "</pre>\n"
      ],
      "text/plain": [
       "20:16:16.306 | \u001b[38;5;160mERROR\u001b[0m   | Flow run\u001b[35m 'incredible-capuchin'\u001b[0m - Encountered exception during execution:\n",
       "Traceback (most recent call last):\n",
       "  File \"c:\\Users\\soham\\anaconda3\\envs\\echodataflow\\lib\\site-packages\\prefect\\engine.py\", line 841, in orchestrate_flow_run\n",
       "    result = await flow_call.aresult()\n",
       "  File \"c:\\Users\\soham\\anaconda3\\envs\\echodataflow\\lib\\site-packages\\prefect\\_internal\\concurrency\\calls.py\", line 293, in aresult\n",
       "    return await asyncio.wrap_future(self.future)\n",
       "  File \"c:\\Users\\soham\\anaconda3\\envs\\echodataflow\\lib\\asyncio\\futures.py\", line 285, in __await__\n",
       "    yield self  # This tells Task to wait for completion.\n",
       "  File \"c:\\Users\\soham\\anaconda3\\envs\\echodataflow\\lib\\asyncio\\tasks.py\", line 304, in __wakeup\n",
       "    future.result()\n",
       "  File \"c:\\Users\\soham\\anaconda3\\envs\\echodataflow\\lib\\asyncio\\futures.py\", line 201, in result\n",
       "    raise self._exception.with_traceback(self._exception_tb)\n",
       "  File \"c:\\Users\\soham\\anaconda3\\envs\\echodataflow\\lib\\site-packages\\prefect\\_internal\\concurrency\\calls.py\", line 318, in _run_sync\n",
       "    result = self.fn(*self.args, **self.kwargs)\n",
       "  File \"c:\\Users\\soham\\anaconda3\\envs\\echodataflow\\lib\\site-packages\\echodataflow\\aspects\\echodataflow_aspect.py\", line 97, in wrapper\n",
       "    raise e\n",
       "  File \"c:\\Users\\soham\\anaconda3\\envs\\echodataflow\\lib\\site-packages\\echodataflow\\aspects\\echodataflow_aspect.py\", line 90, in wrapper\n",
       "    result = func(*args, **kwargs)\n",
       "  File \"c:\\Users\\soham\\anaconda3\\envs\\echodataflow\\lib\\site-packages\\echodataflow\\stages\\subflows\\initialization_flow.py\", line 74, in init_flow\n",
       "    data = club_raw_files(\n",
       "  File \"c:\\Users\\soham\\anaconda3\\envs\\echodataflow\\lib\\site-packages\\prefect\\tasks.py\", line 549, in __call__\n",
       "    return enter_task_run_engine(\n",
       "  File \"c:\\Users\\soham\\anaconda3\\envs\\echodataflow\\lib\\site-packages\\prefect\\engine.py\", line 1156, in enter_task_run_engine\n",
       "    return from_sync.wait_for_call_in_loop_thread(begin_run)\n",
       "  File \"c:\\Users\\soham\\anaconda3\\envs\\echodataflow\\lib\\site-packages\\prefect\\_internal\\concurrency\\api.py\", line 243, in wait_for_call_in_loop_thread\n",
       "    return call.result()\n",
       "  File \"c:\\Users\\soham\\anaconda3\\envs\\echodataflow\\lib\\site-packages\\prefect\\_internal\\concurrency\\calls.py\", line 284, in result\n",
       "    return self.future.result(timeout=timeout)\n",
       "  File \"c:\\Users\\soham\\anaconda3\\envs\\echodataflow\\lib\\site-packages\\prefect\\_internal\\concurrency\\calls.py\", line 168, in result\n",
       "    return self.__get_result()\n",
       "  File \"c:\\Users\\soham\\anaconda3\\envs\\echodataflow\\lib\\concurrent\\futures\\_base.py\", line 403, in __get_result\n",
       "    raise self._exception\n",
       "  File \"c:\\Users\\soham\\anaconda3\\envs\\echodataflow\\lib\\site-packages\\prefect\\_internal\\concurrency\\calls.py\", line 355, in _run_async\n",
       "    result = await coro\n",
       "  File \"c:\\Users\\soham\\anaconda3\\envs\\echodataflow\\lib\\site-packages\\prefect\\engine.py\", line 1324, in get_task_call_return_value\n",
       "    return await future._result()\n",
       "  File \"c:\\Users\\soham\\anaconda3\\envs\\echodataflow\\lib\\site-packages\\prefect\\futures.py\", line 237, in _result\n",
       "    return await final_state.result(raise_on_failure=raise_on_failure, fetch=True)\n",
       "  File \"c:\\Users\\soham\\anaconda3\\envs\\echodataflow\\lib\\site-packages\\prefect\\states.py\", line 91, in _get_state_result\n",
       "    raise await get_state_exception(state)\n",
       "  File \"c:\\Users\\soham\\anaconda3\\envs\\echodataflow\\lib\\site-packages\\prefect\\engine.py\", line 1760, in orchestrate_task_run\n",
       "    result = await call.aresult()\n",
       "  File \"c:\\Users\\soham\\anaconda3\\envs\\echodataflow\\lib\\site-packages\\prefect\\_internal\\concurrency\\calls.py\", line 293, in aresult\n",
       "    return await asyncio.wrap_future(self.future)\n",
       "  File \"c:\\Users\\soham\\anaconda3\\envs\\echodataflow\\lib\\asyncio\\futures.py\", line 285, in __await__\n",
       "    yield self  # This tells Task to wait for completion.\n",
       "  File \"c:\\Users\\soham\\anaconda3\\envs\\echodataflow\\lib\\asyncio\\tasks.py\", line 304, in __wakeup\n",
       "    future.result()\n",
       "  File \"c:\\Users\\soham\\anaconda3\\envs\\echodataflow\\lib\\asyncio\\futures.py\", line 201, in result\n",
       "    raise self._exception.with_traceback(self._exception_tb)\n",
       "  File \"c:\\Users\\soham\\anaconda3\\envs\\echodataflow\\lib\\site-packages\\prefect\\_internal\\concurrency\\calls.py\", line 318, in _run_sync\n",
       "    result = self.fn(*self.args, **self.kwargs)\n",
       "  File \"c:\\Users\\soham\\anaconda3\\envs\\echodataflow\\lib\\site-packages\\echodataflow\\aspects\\echodataflow_aspect.py\", line 97, in wrapper\n",
       "    raise e\n",
       "  File \"c:\\Users\\soham\\anaconda3\\envs\\echodataflow\\lib\\site-packages\\echodataflow\\aspects\\echodataflow_aspect.py\", line 90, in wrapper\n",
       "    result = func(*args, **kwargs)\n",
       "  File \"c:\\Users\\soham\\anaconda3\\envs\\echodataflow\\lib\\site-packages\\echodataflow\\utils\\config_utils.py\", line 440, in club_raw_files\n",
       "    raise ValueError(\"Must have raw_dicts or raw_json_path present.\")\n",
       "ValueError: Must have raw_dicts or raw_json_path present.\n"
      ]
     },
     "metadata": {},
     "output_type": "display_data"
    },
    {
     "data": {
      "text/html": [
       "<pre style=\"white-space:pre;overflow-x:auto;line-height:normal;font-family:Menlo,'DejaVu Sans Mono',consolas,'Courier New',monospace\">20:16:16.384 | <span style=\"color: #d70000; text-decoration-color: #d70000\">ERROR</span>   | Flow run<span style=\"color: #800080; text-decoration-color: #800080\"> 'incredible-capuchin'</span> - Finished in state <span style=\"color: #d70000; text-decoration-color: #d70000\">Failed</span>('Flow run encountered an exception. ValueError: Must have raw_dicts or raw_json_path present.')\n",
       "</pre>\n"
      ],
      "text/plain": [
       "20:16:16.384 | \u001b[38;5;160mERROR\u001b[0m   | Flow run\u001b[35m 'incredible-capuchin'\u001b[0m - Finished in state \u001b[38;5;160mFailed\u001b[0m('Flow run encountered an exception. ValueError: Must have raw_dicts or raw_json_path present.')\n"
      ]
     },
     "metadata": {},
     "output_type": "display_data"
    },
    {
     "data": {
      "text/html": [
       "<pre style=\"white-space:pre;overflow-x:auto;line-height:normal;font-family:Menlo,'DejaVu Sans Mono',consolas,'Courier New',monospace\">20:16:16.386 | <span style=\"color: #d70000; text-decoration-color: #d70000\">ERROR</span>   | Flow run<span style=\"color: #800080; text-decoration-color: #800080\"> 'peach-warthog'</span> - Encountered exception during execution:\n",
       "Traceback (most recent call last):\n",
       "  File \"c:\\Users\\soham\\anaconda3\\envs\\echodataflow\\lib\\site-packages\\prefect\\engine.py\", line 841, in orchestrate_flow_run\n",
       "    result = await flow_call.aresult()\n",
       "  File \"c:\\Users\\soham\\anaconda3\\envs\\echodataflow\\lib\\site-packages\\prefect\\_internal\\concurrency\\calls.py\", line 293, in aresult\n",
       "    return await asyncio.wrap_future(self.future)\n",
       "  File \"c:\\Users\\soham\\anaconda3\\envs\\echodataflow\\lib\\asyncio\\futures.py\", line 285, in __await__\n",
       "    yield self  # This tells Task to wait for completion.\n",
       "  File \"c:\\Users\\soham\\anaconda3\\envs\\echodataflow\\lib\\asyncio\\tasks.py\", line 304, in __wakeup\n",
       "    future.result()\n",
       "  File \"c:\\Users\\soham\\anaconda3\\envs\\echodataflow\\lib\\asyncio\\futures.py\", line 201, in result\n",
       "    raise self._exception.with_traceback(self._exception_tb)\n",
       "  File \"c:\\Users\\soham\\anaconda3\\envs\\echodataflow\\lib\\site-packages\\prefect\\_internal\\concurrency\\calls.py\", line 318, in _run_sync\n",
       "    result = self.fn(*self.args, **self.kwargs)\n",
       "  File \"c:\\Users\\soham\\anaconda3\\envs\\echodataflow\\lib\\site-packages\\echodataflow\\stages\\echodataflow_trigger.py\", line 170, in echodataflow_trigger\n",
       "    return init_flow(config=dataset, pipeline=pipeline, json_data_path=json_data_path)\n",
       "  File \"c:\\Users\\soham\\anaconda3\\envs\\echodataflow\\lib\\site-packages\\prefect\\flows.py\", line 1097, in __call__\n",
       "    return enter_flow_run_engine_from_flow_call(\n",
       "  File \"c:\\Users\\soham\\anaconda3\\envs\\echodataflow\\lib\\site-packages\\prefect\\engine.py\", line 283, in enter_flow_run_engine_from_flow_call\n",
       "    retval = from_sync.wait_for_call_in_loop_thread(\n",
       "  File \"c:\\Users\\soham\\anaconda3\\envs\\echodataflow\\lib\\site-packages\\prefect\\_internal\\concurrency\\api.py\", line 243, in wait_for_call_in_loop_thread\n",
       "    return call.result()\n",
       "  File \"c:\\Users\\soham\\anaconda3\\envs\\echodataflow\\lib\\site-packages\\prefect\\_internal\\concurrency\\calls.py\", line 284, in result\n",
       "    return self.future.result(timeout=timeout)\n",
       "  File \"c:\\Users\\soham\\anaconda3\\envs\\echodataflow\\lib\\site-packages\\prefect\\_internal\\concurrency\\calls.py\", line 168, in result\n",
       "    return self.__get_result()\n",
       "  File \"c:\\Users\\soham\\anaconda3\\envs\\echodataflow\\lib\\concurrent\\futures\\_base.py\", line 403, in __get_result\n",
       "    raise self._exception\n",
       "  File \"c:\\Users\\soham\\anaconda3\\envs\\echodataflow\\lib\\site-packages\\prefect\\_internal\\concurrency\\calls.py\", line 355, in _run_async\n",
       "    result = await coro\n",
       "  File \"c:\\Users\\soham\\anaconda3\\envs\\echodataflow\\lib\\site-packages\\prefect\\client\\utilities.py\", line 51, in with_injected_client\n",
       "    return await fn(*args, **kwargs)\n",
       "  File \"c:\\Users\\soham\\anaconda3\\envs\\echodataflow\\lib\\site-packages\\prefect\\engine.py\", line 725, in create_and_begin_subflow_run\n",
       "    return await terminal_state.result(fetch=True)\n",
       "  File \"c:\\Users\\soham\\anaconda3\\envs\\echodataflow\\lib\\site-packages\\prefect\\states.py\", line 91, in _get_state_result\n",
       "    raise await get_state_exception(state)\n",
       "  File \"c:\\Users\\soham\\anaconda3\\envs\\echodataflow\\lib\\site-packages\\prefect\\engine.py\", line 841, in orchestrate_flow_run\n",
       "    result = await flow_call.aresult()\n",
       "  File \"c:\\Users\\soham\\anaconda3\\envs\\echodataflow\\lib\\site-packages\\prefect\\_internal\\concurrency\\calls.py\", line 293, in aresult\n",
       "    return await asyncio.wrap_future(self.future)\n",
       "  File \"c:\\Users\\soham\\anaconda3\\envs\\echodataflow\\lib\\asyncio\\futures.py\", line 285, in __await__\n",
       "    yield self  # This tells Task to wait for completion.\n",
       "  File \"c:\\Users\\soham\\anaconda3\\envs\\echodataflow\\lib\\asyncio\\tasks.py\", line 304, in __wakeup\n",
       "    future.result()\n",
       "  File \"c:\\Users\\soham\\anaconda3\\envs\\echodataflow\\lib\\asyncio\\futures.py\", line 201, in result\n",
       "    raise self._exception.with_traceback(self._exception_tb)\n",
       "  File \"c:\\Users\\soham\\anaconda3\\envs\\echodataflow\\lib\\site-packages\\prefect\\_internal\\concurrency\\calls.py\", line 318, in _run_sync\n",
       "    result = self.fn(*self.args, **self.kwargs)\n",
       "  File \"c:\\Users\\soham\\anaconda3\\envs\\echodataflow\\lib\\site-packages\\echodataflow\\aspects\\echodataflow_aspect.py\", line 97, in wrapper\n",
       "    raise e\n",
       "  File \"c:\\Users\\soham\\anaconda3\\envs\\echodataflow\\lib\\site-packages\\echodataflow\\aspects\\echodataflow_aspect.py\", line 90, in wrapper\n",
       "    result = func(*args, **kwargs)\n",
       "  File \"c:\\Users\\soham\\anaconda3\\envs\\echodataflow\\lib\\site-packages\\echodataflow\\stages\\subflows\\initialization_flow.py\", line 74, in init_flow\n",
       "    data = club_raw_files(\n",
       "  File \"c:\\Users\\soham\\anaconda3\\envs\\echodataflow\\lib\\site-packages\\prefect\\tasks.py\", line 549, in __call__\n",
       "    return enter_task_run_engine(\n",
       "  File \"c:\\Users\\soham\\anaconda3\\envs\\echodataflow\\lib\\site-packages\\prefect\\engine.py\", line 1156, in enter_task_run_engine\n",
       "    return from_sync.wait_for_call_in_loop_thread(begin_run)\n",
       "  File \"c:\\Users\\soham\\anaconda3\\envs\\echodataflow\\lib\\site-packages\\prefect\\_internal\\concurrency\\api.py\", line 243, in wait_for_call_in_loop_thread\n",
       "    return call.result()\n",
       "  File \"c:\\Users\\soham\\anaconda3\\envs\\echodataflow\\lib\\site-packages\\prefect\\_internal\\concurrency\\calls.py\", line 284, in result\n",
       "    return self.future.result(timeout=timeout)\n",
       "  File \"c:\\Users\\soham\\anaconda3\\envs\\echodataflow\\lib\\site-packages\\prefect\\_internal\\concurrency\\calls.py\", line 168, in result\n",
       "    return self.__get_result()\n",
       "  File \"c:\\Users\\soham\\anaconda3\\envs\\echodataflow\\lib\\concurrent\\futures\\_base.py\", line 403, in __get_result\n",
       "    raise self._exception\n",
       "  File \"c:\\Users\\soham\\anaconda3\\envs\\echodataflow\\lib\\site-packages\\prefect\\_internal\\concurrency\\calls.py\", line 355, in _run_async\n",
       "    result = await coro\n",
       "  File \"c:\\Users\\soham\\anaconda3\\envs\\echodataflow\\lib\\site-packages\\prefect\\engine.py\", line 1324, in get_task_call_return_value\n",
       "    return await future._result()\n",
       "  File \"c:\\Users\\soham\\anaconda3\\envs\\echodataflow\\lib\\site-packages\\prefect\\futures.py\", line 237, in _result\n",
       "    return await final_state.result(raise_on_failure=raise_on_failure, fetch=True)\n",
       "  File \"c:\\Users\\soham\\anaconda3\\envs\\echodataflow\\lib\\site-packages\\prefect\\states.py\", line 91, in _get_state_result\n",
       "    raise await get_state_exception(state)\n",
       "  File \"c:\\Users\\soham\\anaconda3\\envs\\echodataflow\\lib\\site-packages\\prefect\\engine.py\", line 1760, in orchestrate_task_run\n",
       "    result = await call.aresult()\n",
       "  File \"c:\\Users\\soham\\anaconda3\\envs\\echodataflow\\lib\\site-packages\\prefect\\_internal\\concurrency\\calls.py\", line 293, in aresult\n",
       "    return await asyncio.wrap_future(self.future)\n",
       "  File \"c:\\Users\\soham\\anaconda3\\envs\\echodataflow\\lib\\asyncio\\futures.py\", line 285, in __await__\n",
       "    yield self  # This tells Task to wait for completion.\n",
       "  File \"c:\\Users\\soham\\anaconda3\\envs\\echodataflow\\lib\\asyncio\\tasks.py\", line 304, in __wakeup\n",
       "    future.result()\n",
       "  File \"c:\\Users\\soham\\anaconda3\\envs\\echodataflow\\lib\\asyncio\\futures.py\", line 201, in result\n",
       "    raise self._exception.with_traceback(self._exception_tb)\n",
       "  File \"c:\\Users\\soham\\anaconda3\\envs\\echodataflow\\lib\\site-packages\\prefect\\_internal\\concurrency\\calls.py\", line 318, in _run_sync\n",
       "    result = self.fn(*self.args, **self.kwargs)\n",
       "  File \"c:\\Users\\soham\\anaconda3\\envs\\echodataflow\\lib\\site-packages\\echodataflow\\aspects\\echodataflow_aspect.py\", line 97, in wrapper\n",
       "    raise e\n",
       "  File \"c:\\Users\\soham\\anaconda3\\envs\\echodataflow\\lib\\site-packages\\echodataflow\\aspects\\echodataflow_aspect.py\", line 90, in wrapper\n",
       "    result = func(*args, **kwargs)\n",
       "  File \"c:\\Users\\soham\\anaconda3\\envs\\echodataflow\\lib\\site-packages\\echodataflow\\utils\\config_utils.py\", line 440, in club_raw_files\n",
       "    raise ValueError(\"Must have raw_dicts or raw_json_path present.\")\n",
       "ValueError: Must have raw_dicts or raw_json_path present.\n",
       "</pre>\n"
      ],
      "text/plain": [
       "20:16:16.386 | \u001b[38;5;160mERROR\u001b[0m   | Flow run\u001b[35m 'peach-warthog'\u001b[0m - Encountered exception during execution:\n",
       "Traceback (most recent call last):\n",
       "  File \"c:\\Users\\soham\\anaconda3\\envs\\echodataflow\\lib\\site-packages\\prefect\\engine.py\", line 841, in orchestrate_flow_run\n",
       "    result = await flow_call.aresult()\n",
       "  File \"c:\\Users\\soham\\anaconda3\\envs\\echodataflow\\lib\\site-packages\\prefect\\_internal\\concurrency\\calls.py\", line 293, in aresult\n",
       "    return await asyncio.wrap_future(self.future)\n",
       "  File \"c:\\Users\\soham\\anaconda3\\envs\\echodataflow\\lib\\asyncio\\futures.py\", line 285, in __await__\n",
       "    yield self  # This tells Task to wait for completion.\n",
       "  File \"c:\\Users\\soham\\anaconda3\\envs\\echodataflow\\lib\\asyncio\\tasks.py\", line 304, in __wakeup\n",
       "    future.result()\n",
       "  File \"c:\\Users\\soham\\anaconda3\\envs\\echodataflow\\lib\\asyncio\\futures.py\", line 201, in result\n",
       "    raise self._exception.with_traceback(self._exception_tb)\n",
       "  File \"c:\\Users\\soham\\anaconda3\\envs\\echodataflow\\lib\\site-packages\\prefect\\_internal\\concurrency\\calls.py\", line 318, in _run_sync\n",
       "    result = self.fn(*self.args, **self.kwargs)\n",
       "  File \"c:\\Users\\soham\\anaconda3\\envs\\echodataflow\\lib\\site-packages\\echodataflow\\stages\\echodataflow_trigger.py\", line 170, in echodataflow_trigger\n",
       "    return init_flow(config=dataset, pipeline=pipeline, json_data_path=json_data_path)\n",
       "  File \"c:\\Users\\soham\\anaconda3\\envs\\echodataflow\\lib\\site-packages\\prefect\\flows.py\", line 1097, in __call__\n",
       "    return enter_flow_run_engine_from_flow_call(\n",
       "  File \"c:\\Users\\soham\\anaconda3\\envs\\echodataflow\\lib\\site-packages\\prefect\\engine.py\", line 283, in enter_flow_run_engine_from_flow_call\n",
       "    retval = from_sync.wait_for_call_in_loop_thread(\n",
       "  File \"c:\\Users\\soham\\anaconda3\\envs\\echodataflow\\lib\\site-packages\\prefect\\_internal\\concurrency\\api.py\", line 243, in wait_for_call_in_loop_thread\n",
       "    return call.result()\n",
       "  File \"c:\\Users\\soham\\anaconda3\\envs\\echodataflow\\lib\\site-packages\\prefect\\_internal\\concurrency\\calls.py\", line 284, in result\n",
       "    return self.future.result(timeout=timeout)\n",
       "  File \"c:\\Users\\soham\\anaconda3\\envs\\echodataflow\\lib\\site-packages\\prefect\\_internal\\concurrency\\calls.py\", line 168, in result\n",
       "    return self.__get_result()\n",
       "  File \"c:\\Users\\soham\\anaconda3\\envs\\echodataflow\\lib\\concurrent\\futures\\_base.py\", line 403, in __get_result\n",
       "    raise self._exception\n",
       "  File \"c:\\Users\\soham\\anaconda3\\envs\\echodataflow\\lib\\site-packages\\prefect\\_internal\\concurrency\\calls.py\", line 355, in _run_async\n",
       "    result = await coro\n",
       "  File \"c:\\Users\\soham\\anaconda3\\envs\\echodataflow\\lib\\site-packages\\prefect\\client\\utilities.py\", line 51, in with_injected_client\n",
       "    return await fn(*args, **kwargs)\n",
       "  File \"c:\\Users\\soham\\anaconda3\\envs\\echodataflow\\lib\\site-packages\\prefect\\engine.py\", line 725, in create_and_begin_subflow_run\n",
       "    return await terminal_state.result(fetch=True)\n",
       "  File \"c:\\Users\\soham\\anaconda3\\envs\\echodataflow\\lib\\site-packages\\prefect\\states.py\", line 91, in _get_state_result\n",
       "    raise await get_state_exception(state)\n",
       "  File \"c:\\Users\\soham\\anaconda3\\envs\\echodataflow\\lib\\site-packages\\prefect\\engine.py\", line 841, in orchestrate_flow_run\n",
       "    result = await flow_call.aresult()\n",
       "  File \"c:\\Users\\soham\\anaconda3\\envs\\echodataflow\\lib\\site-packages\\prefect\\_internal\\concurrency\\calls.py\", line 293, in aresult\n",
       "    return await asyncio.wrap_future(self.future)\n",
       "  File \"c:\\Users\\soham\\anaconda3\\envs\\echodataflow\\lib\\asyncio\\futures.py\", line 285, in __await__\n",
       "    yield self  # This tells Task to wait for completion.\n",
       "  File \"c:\\Users\\soham\\anaconda3\\envs\\echodataflow\\lib\\asyncio\\tasks.py\", line 304, in __wakeup\n",
       "    future.result()\n",
       "  File \"c:\\Users\\soham\\anaconda3\\envs\\echodataflow\\lib\\asyncio\\futures.py\", line 201, in result\n",
       "    raise self._exception.with_traceback(self._exception_tb)\n",
       "  File \"c:\\Users\\soham\\anaconda3\\envs\\echodataflow\\lib\\site-packages\\prefect\\_internal\\concurrency\\calls.py\", line 318, in _run_sync\n",
       "    result = self.fn(*self.args, **self.kwargs)\n",
       "  File \"c:\\Users\\soham\\anaconda3\\envs\\echodataflow\\lib\\site-packages\\echodataflow\\aspects\\echodataflow_aspect.py\", line 97, in wrapper\n",
       "    raise e\n",
       "  File \"c:\\Users\\soham\\anaconda3\\envs\\echodataflow\\lib\\site-packages\\echodataflow\\aspects\\echodataflow_aspect.py\", line 90, in wrapper\n",
       "    result = func(*args, **kwargs)\n",
       "  File \"c:\\Users\\soham\\anaconda3\\envs\\echodataflow\\lib\\site-packages\\echodataflow\\stages\\subflows\\initialization_flow.py\", line 74, in init_flow\n",
       "    data = club_raw_files(\n",
       "  File \"c:\\Users\\soham\\anaconda3\\envs\\echodataflow\\lib\\site-packages\\prefect\\tasks.py\", line 549, in __call__\n",
       "    return enter_task_run_engine(\n",
       "  File \"c:\\Users\\soham\\anaconda3\\envs\\echodataflow\\lib\\site-packages\\prefect\\engine.py\", line 1156, in enter_task_run_engine\n",
       "    return from_sync.wait_for_call_in_loop_thread(begin_run)\n",
       "  File \"c:\\Users\\soham\\anaconda3\\envs\\echodataflow\\lib\\site-packages\\prefect\\_internal\\concurrency\\api.py\", line 243, in wait_for_call_in_loop_thread\n",
       "    return call.result()\n",
       "  File \"c:\\Users\\soham\\anaconda3\\envs\\echodataflow\\lib\\site-packages\\prefect\\_internal\\concurrency\\calls.py\", line 284, in result\n",
       "    return self.future.result(timeout=timeout)\n",
       "  File \"c:\\Users\\soham\\anaconda3\\envs\\echodataflow\\lib\\site-packages\\prefect\\_internal\\concurrency\\calls.py\", line 168, in result\n",
       "    return self.__get_result()\n",
       "  File \"c:\\Users\\soham\\anaconda3\\envs\\echodataflow\\lib\\concurrent\\futures\\_base.py\", line 403, in __get_result\n",
       "    raise self._exception\n",
       "  File \"c:\\Users\\soham\\anaconda3\\envs\\echodataflow\\lib\\site-packages\\prefect\\_internal\\concurrency\\calls.py\", line 355, in _run_async\n",
       "    result = await coro\n",
       "  File \"c:\\Users\\soham\\anaconda3\\envs\\echodataflow\\lib\\site-packages\\prefect\\engine.py\", line 1324, in get_task_call_return_value\n",
       "    return await future._result()\n",
       "  File \"c:\\Users\\soham\\anaconda3\\envs\\echodataflow\\lib\\site-packages\\prefect\\futures.py\", line 237, in _result\n",
       "    return await final_state.result(raise_on_failure=raise_on_failure, fetch=True)\n",
       "  File \"c:\\Users\\soham\\anaconda3\\envs\\echodataflow\\lib\\site-packages\\prefect\\states.py\", line 91, in _get_state_result\n",
       "    raise await get_state_exception(state)\n",
       "  File \"c:\\Users\\soham\\anaconda3\\envs\\echodataflow\\lib\\site-packages\\prefect\\engine.py\", line 1760, in orchestrate_task_run\n",
       "    result = await call.aresult()\n",
       "  File \"c:\\Users\\soham\\anaconda3\\envs\\echodataflow\\lib\\site-packages\\prefect\\_internal\\concurrency\\calls.py\", line 293, in aresult\n",
       "    return await asyncio.wrap_future(self.future)\n",
       "  File \"c:\\Users\\soham\\anaconda3\\envs\\echodataflow\\lib\\asyncio\\futures.py\", line 285, in __await__\n",
       "    yield self  # This tells Task to wait for completion.\n",
       "  File \"c:\\Users\\soham\\anaconda3\\envs\\echodataflow\\lib\\asyncio\\tasks.py\", line 304, in __wakeup\n",
       "    future.result()\n",
       "  File \"c:\\Users\\soham\\anaconda3\\envs\\echodataflow\\lib\\asyncio\\futures.py\", line 201, in result\n",
       "    raise self._exception.with_traceback(self._exception_tb)\n",
       "  File \"c:\\Users\\soham\\anaconda3\\envs\\echodataflow\\lib\\site-packages\\prefect\\_internal\\concurrency\\calls.py\", line 318, in _run_sync\n",
       "    result = self.fn(*self.args, **self.kwargs)\n",
       "  File \"c:\\Users\\soham\\anaconda3\\envs\\echodataflow\\lib\\site-packages\\echodataflow\\aspects\\echodataflow_aspect.py\", line 97, in wrapper\n",
       "    raise e\n",
       "  File \"c:\\Users\\soham\\anaconda3\\envs\\echodataflow\\lib\\site-packages\\echodataflow\\aspects\\echodataflow_aspect.py\", line 90, in wrapper\n",
       "    result = func(*args, **kwargs)\n",
       "  File \"c:\\Users\\soham\\anaconda3\\envs\\echodataflow\\lib\\site-packages\\echodataflow\\utils\\config_utils.py\", line 440, in club_raw_files\n",
       "    raise ValueError(\"Must have raw_dicts or raw_json_path present.\")\n",
       "ValueError: Must have raw_dicts or raw_json_path present.\n"
      ]
     },
     "metadata": {},
     "output_type": "display_data"
    },
    {
     "data": {
      "text/html": [
       "<pre style=\"white-space:pre;overflow-x:auto;line-height:normal;font-family:Menlo,'DejaVu Sans Mono',consolas,'Courier New',monospace\">20:16:16.432 | <span style=\"color: #d70000; text-decoration-color: #d70000\">ERROR</span>   | Flow run<span style=\"color: #800080; text-decoration-color: #800080\"> 'peach-warthog'</span> - Finished in state <span style=\"color: #d70000; text-decoration-color: #d70000\">Failed</span>('Flow run encountered an exception. ValueError: Must have raw_dicts or raw_json_path present.')\n",
       "</pre>\n"
      ],
      "text/plain": [
       "20:16:16.432 | \u001b[38;5;160mERROR\u001b[0m   | Flow run\u001b[35m 'peach-warthog'\u001b[0m - Finished in state \u001b[38;5;160mFailed\u001b[0m('Flow run encountered an exception. ValueError: Must have raw_dicts or raw_json_path present.')\n"
      ]
     },
     "metadata": {},
     "output_type": "display_data"
    },
    {
     "ename": "ValueError",
     "evalue": "Must have raw_dicts or raw_json_path present.",
     "output_type": "error",
     "traceback": [
      "\u001b[1;31m---------------------------------------------------------------------------\u001b[0m",
      "\u001b[1;31mValueError\u001b[0m                                Traceback (most recent call last)",
      "Cell \u001b[1;32mIn[4], line 2\u001b[0m\n\u001b[0;32m      1\u001b[0m options \u001b[38;5;241m=\u001b[39m {\u001b[38;5;124m\"\u001b[39m\u001b[38;5;124mstorage_options_override\u001b[39m\u001b[38;5;124m\"\u001b[39m: \u001b[38;5;28;01mFalse\u001b[39;00m}\n\u001b[1;32m----> 2\u001b[0m data  \u001b[38;5;241m=\u001b[39m \u001b[43mechodataflow_start\u001b[49m\u001b[43m(\u001b[49m\u001b[43mdataset_config\u001b[49m\u001b[38;5;241;43m=\u001b[39;49m\u001b[43mdataset_config\u001b[49m\u001b[43m,\u001b[49m\u001b[43m \u001b[49m\u001b[43mpipeline_config\u001b[49m\u001b[38;5;241;43m=\u001b[39;49m\u001b[43mpipeline_config\u001b[49m\u001b[43m,\u001b[49m\u001b[43m \u001b[49m\u001b[43moptions\u001b[49m\u001b[38;5;241;43m=\u001b[39;49m\u001b[43moptions\u001b[49m\u001b[43m)\u001b[49m\n",
      "File \u001b[1;32mc:\\Users\\soham\\anaconda3\\envs\\echodataflow\\lib\\site-packages\\echodataflow\\stages\\echodataflow.py:260\u001b[0m, in \u001b[0;36mechodataflow_start\u001b[1;34m(dataset_config, pipeline_config, logging_config, storage_options, options, json_data_path)\u001b[0m\n\u001b[0;32m    258\u001b[0m \u001b[38;5;28mprint\u001b[39m(\u001b[38;5;124m\"\u001b[39m\u001b[38;5;130;01m\\n\u001b[39;00m\u001b[38;5;124mStarting the Pipeline\u001b[39m\u001b[38;5;124m\"\u001b[39m)\n\u001b[0;32m    259\u001b[0m \u001b[38;5;66;03m# Call the actual pipeline\u001b[39;00m\n\u001b[1;32m--> 260\u001b[0m \u001b[38;5;28;01mreturn\u001b[39;00m \u001b[43mechodataflow_trigger\u001b[49m\u001b[43m(\u001b[49m\n\u001b[0;32m    261\u001b[0m \u001b[43m    \u001b[49m\u001b[43mdataset_config\u001b[49m\u001b[38;5;241;43m=\u001b[39;49m\u001b[43mdataset_config\u001b[49m\u001b[43m,\u001b[49m\n\u001b[0;32m    262\u001b[0m \u001b[43m    \u001b[49m\u001b[43mpipeline_config\u001b[49m\u001b[38;5;241;43m=\u001b[39;49m\u001b[43mpipeline_config\u001b[49m\u001b[43m,\u001b[49m\n\u001b[0;32m    263\u001b[0m \u001b[43m    \u001b[49m\u001b[43mlogging_config\u001b[49m\u001b[38;5;241;43m=\u001b[39;49m\u001b[43mlogging_config\u001b[49m\u001b[43m,\u001b[49m\n\u001b[0;32m    264\u001b[0m \u001b[43m    \u001b[49m\u001b[43mstorage_options\u001b[49m\u001b[38;5;241;43m=\u001b[39;49m\u001b[43mstorage_options\u001b[49m\u001b[43m,\u001b[49m\n\u001b[0;32m    265\u001b[0m \u001b[43m    \u001b[49m\u001b[43moptions\u001b[49m\u001b[38;5;241;43m=\u001b[39;49m\u001b[43moptions\u001b[49m\u001b[43m,\u001b[49m\n\u001b[0;32m    266\u001b[0m \u001b[43m    \u001b[49m\u001b[43mjson_data_path\u001b[49m\u001b[38;5;241;43m=\u001b[39;49m\u001b[43mjson_data_path\u001b[49m\n\u001b[0;32m    267\u001b[0m \u001b[43m\u001b[49m\u001b[43m)\u001b[49m\n",
      "File \u001b[1;32mc:\\Users\\soham\\anaconda3\\envs\\echodataflow\\lib\\site-packages\\prefect\\flows.py:1097\u001b[0m, in \u001b[0;36mFlow.__call__\u001b[1;34m(self, return_state, wait_for, *args, **kwargs)\u001b[0m\n\u001b[0;32m   1092\u001b[0m \u001b[38;5;28;01mif\u001b[39;00m task_viz_tracker:\n\u001b[0;32m   1093\u001b[0m     \u001b[38;5;66;03m# this is a subflow, for now return a single task and do not go further\u001b[39;00m\n\u001b[0;32m   1094\u001b[0m     \u001b[38;5;66;03m# we can add support for exploring subflows for tasks in the future.\u001b[39;00m\n\u001b[0;32m   1095\u001b[0m     \u001b[38;5;28;01mreturn\u001b[39;00m track_viz_task(\u001b[38;5;28mself\u001b[39m\u001b[38;5;241m.\u001b[39misasync, \u001b[38;5;28mself\u001b[39m\u001b[38;5;241m.\u001b[39mname, parameters)\n\u001b[1;32m-> 1097\u001b[0m \u001b[38;5;28;01mreturn\u001b[39;00m \u001b[43menter_flow_run_engine_from_flow_call\u001b[49m\u001b[43m(\u001b[49m\n\u001b[0;32m   1098\u001b[0m \u001b[43m    \u001b[49m\u001b[38;5;28;43mself\u001b[39;49m\u001b[43m,\u001b[49m\n\u001b[0;32m   1099\u001b[0m \u001b[43m    \u001b[49m\u001b[43mparameters\u001b[49m\u001b[43m,\u001b[49m\n\u001b[0;32m   1100\u001b[0m \u001b[43m    \u001b[49m\u001b[43mwait_for\u001b[49m\u001b[38;5;241;43m=\u001b[39;49m\u001b[43mwait_for\u001b[49m\u001b[43m,\u001b[49m\n\u001b[0;32m   1101\u001b[0m \u001b[43m    \u001b[49m\u001b[43mreturn_type\u001b[49m\u001b[38;5;241;43m=\u001b[39;49m\u001b[43mreturn_type\u001b[49m\u001b[43m,\u001b[49m\n\u001b[0;32m   1102\u001b[0m \u001b[43m\u001b[49m\u001b[43m)\u001b[49m\n",
      "File \u001b[1;32mc:\\Users\\soham\\anaconda3\\envs\\echodataflow\\lib\\site-packages\\prefect\\engine.py:283\u001b[0m, in \u001b[0;36menter_flow_run_engine_from_flow_call\u001b[1;34m(flow, parameters, wait_for, return_type)\u001b[0m\n\u001b[0;32m    276\u001b[0m     retval \u001b[38;5;241m=\u001b[39m from_async\u001b[38;5;241m.\u001b[39mwait_for_call_in_loop_thread(\n\u001b[0;32m    277\u001b[0m         begin_run,\n\u001b[0;32m    278\u001b[0m         done_callbacks\u001b[38;5;241m=\u001b[39mdone_callbacks,\n\u001b[0;32m    279\u001b[0m         contexts\u001b[38;5;241m=\u001b[39mcontexts,\n\u001b[0;32m    280\u001b[0m     )\n\u001b[0;32m    282\u001b[0m \u001b[38;5;28;01melse\u001b[39;00m:\n\u001b[1;32m--> 283\u001b[0m     retval \u001b[38;5;241m=\u001b[39m \u001b[43mfrom_sync\u001b[49m\u001b[38;5;241;43m.\u001b[39;49m\u001b[43mwait_for_call_in_loop_thread\u001b[49m\u001b[43m(\u001b[49m\n\u001b[0;32m    284\u001b[0m \u001b[43m        \u001b[49m\u001b[43mbegin_run\u001b[49m\u001b[43m,\u001b[49m\n\u001b[0;32m    285\u001b[0m \u001b[43m        \u001b[49m\u001b[43mdone_callbacks\u001b[49m\u001b[38;5;241;43m=\u001b[39;49m\u001b[43mdone_callbacks\u001b[49m\u001b[43m,\u001b[49m\n\u001b[0;32m    286\u001b[0m \u001b[43m        \u001b[49m\u001b[43mcontexts\u001b[49m\u001b[38;5;241;43m=\u001b[39;49m\u001b[43mcontexts\u001b[49m\u001b[43m,\u001b[49m\n\u001b[0;32m    287\u001b[0m \u001b[43m    \u001b[49m\u001b[43m)\u001b[49m\n\u001b[0;32m    289\u001b[0m \u001b[38;5;28;01mreturn\u001b[39;00m retval\n",
      "File \u001b[1;32mc:\\Users\\soham\\anaconda3\\envs\\echodataflow\\lib\\site-packages\\prefect\\_internal\\concurrency\\api.py:243\u001b[0m, in \u001b[0;36mfrom_sync.wait_for_call_in_loop_thread\u001b[1;34m(_from_sync__call, timeout, done_callbacks, contexts)\u001b[0m\n\u001b[0;32m    241\u001b[0m     stack\u001b[38;5;241m.\u001b[39menter_context(context)\n\u001b[0;32m    242\u001b[0m waiter\u001b[38;5;241m.\u001b[39mwait()\n\u001b[1;32m--> 243\u001b[0m \u001b[38;5;28;01mreturn\u001b[39;00m \u001b[43mcall\u001b[49m\u001b[38;5;241;43m.\u001b[39;49m\u001b[43mresult\u001b[49m\u001b[43m(\u001b[49m\u001b[43m)\u001b[49m\n",
      "File \u001b[1;32mc:\\Users\\soham\\anaconda3\\envs\\echodataflow\\lib\\site-packages\\prefect\\_internal\\concurrency\\calls.py:284\u001b[0m, in \u001b[0;36mCall.result\u001b[1;34m(self, timeout)\u001b[0m\n\u001b[0;32m    278\u001b[0m \u001b[38;5;28;01mdef\u001b[39;00m \u001b[38;5;21mresult\u001b[39m(\u001b[38;5;28mself\u001b[39m, timeout: Optional[\u001b[38;5;28mfloat\u001b[39m] \u001b[38;5;241m=\u001b[39m \u001b[38;5;28;01mNone\u001b[39;00m) \u001b[38;5;241m-\u001b[39m\u001b[38;5;241m>\u001b[39m T:\n\u001b[0;32m    279\u001b[0m \u001b[38;5;250m    \u001b[39m\u001b[38;5;124;03m\"\"\"\u001b[39;00m\n\u001b[0;32m    280\u001b[0m \u001b[38;5;124;03m    Wait for the result of the call.\u001b[39;00m\n\u001b[0;32m    281\u001b[0m \n\u001b[0;32m    282\u001b[0m \u001b[38;5;124;03m    Not safe for use from asynchronous contexts.\u001b[39;00m\n\u001b[0;32m    283\u001b[0m \u001b[38;5;124;03m    \"\"\"\u001b[39;00m\n\u001b[1;32m--> 284\u001b[0m     \u001b[38;5;28;01mreturn\u001b[39;00m \u001b[38;5;28;43mself\u001b[39;49m\u001b[38;5;241;43m.\u001b[39;49m\u001b[43mfuture\u001b[49m\u001b[38;5;241;43m.\u001b[39;49m\u001b[43mresult\u001b[49m\u001b[43m(\u001b[49m\u001b[43mtimeout\u001b[49m\u001b[38;5;241;43m=\u001b[39;49m\u001b[43mtimeout\u001b[49m\u001b[43m)\u001b[49m\n",
      "File \u001b[1;32mc:\\Users\\soham\\anaconda3\\envs\\echodataflow\\lib\\site-packages\\prefect\\_internal\\concurrency\\calls.py:168\u001b[0m, in \u001b[0;36mFuture.result\u001b[1;34m(self, timeout)\u001b[0m\n\u001b[0;32m    166\u001b[0m     \u001b[38;5;28;01mraise\u001b[39;00m CancelledError()\n\u001b[0;32m    167\u001b[0m \u001b[38;5;28;01melif\u001b[39;00m \u001b[38;5;28mself\u001b[39m\u001b[38;5;241m.\u001b[39m_state \u001b[38;5;241m==\u001b[39m FINISHED:\n\u001b[1;32m--> 168\u001b[0m     \u001b[38;5;28;01mreturn\u001b[39;00m \u001b[38;5;28;43mself\u001b[39;49m\u001b[38;5;241;43m.\u001b[39;49m\u001b[43m__get_result\u001b[49m\u001b[43m(\u001b[49m\u001b[43m)\u001b[49m\n\u001b[0;32m    170\u001b[0m \u001b[38;5;28mself\u001b[39m\u001b[38;5;241m.\u001b[39m_condition\u001b[38;5;241m.\u001b[39mwait(timeout)\n\u001b[0;32m    172\u001b[0m \u001b[38;5;28;01mif\u001b[39;00m \u001b[38;5;28mself\u001b[39m\u001b[38;5;241m.\u001b[39m_state \u001b[38;5;129;01min\u001b[39;00m [CANCELLED, CANCELLED_AND_NOTIFIED]:\n\u001b[0;32m    173\u001b[0m     \u001b[38;5;66;03m# Raise Prefect cancelled error instead of\u001b[39;00m\n\u001b[0;32m    174\u001b[0m     \u001b[38;5;66;03m# `concurrent.futures._base.CancelledError`\u001b[39;00m\n",
      "File \u001b[1;32mc:\\Users\\soham\\anaconda3\\envs\\echodataflow\\lib\\concurrent\\futures\\_base.py:403\u001b[0m, in \u001b[0;36mFuture.__get_result\u001b[1;34m(self)\u001b[0m\n\u001b[0;32m    401\u001b[0m \u001b[38;5;28;01mif\u001b[39;00m \u001b[38;5;28mself\u001b[39m\u001b[38;5;241m.\u001b[39m_exception:\n\u001b[0;32m    402\u001b[0m     \u001b[38;5;28;01mtry\u001b[39;00m:\n\u001b[1;32m--> 403\u001b[0m         \u001b[38;5;28;01mraise\u001b[39;00m \u001b[38;5;28mself\u001b[39m\u001b[38;5;241m.\u001b[39m_exception\n\u001b[0;32m    404\u001b[0m     \u001b[38;5;28;01mfinally\u001b[39;00m:\n\u001b[0;32m    405\u001b[0m         \u001b[38;5;66;03m# Break a reference cycle with the exception in self._exception\u001b[39;00m\n\u001b[0;32m    406\u001b[0m         \u001b[38;5;28mself\u001b[39m \u001b[38;5;241m=\u001b[39m \u001b[38;5;28;01mNone\u001b[39;00m\n",
      "File \u001b[1;32mc:\\Users\\soham\\anaconda3\\envs\\echodataflow\\lib\\site-packages\\prefect\\_internal\\concurrency\\calls.py:355\u001b[0m, in \u001b[0;36mCall._run_async\u001b[1;34m(***failed resolving arguments***)\u001b[0m\n\u001b[0;32m    353\u001b[0m \u001b[38;5;28;01mwith\u001b[39;00m \u001b[38;5;28mself\u001b[39m\u001b[38;5;241m.\u001b[39mfuture\u001b[38;5;241m.\u001b[39menforce_async_deadline() \u001b[38;5;28;01mas\u001b[39;00m cancel_scope:\n\u001b[0;32m    354\u001b[0m     \u001b[38;5;28;01mtry\u001b[39;00m:\n\u001b[1;32m--> 355\u001b[0m         result \u001b[38;5;241m=\u001b[39m \u001b[38;5;28;01mawait\u001b[39;00m coro\n\u001b[0;32m    356\u001b[0m     \u001b[38;5;28;01mfinally\u001b[39;00m:\n\u001b[0;32m    357\u001b[0m         \u001b[38;5;66;03m# Forget this call's arguments in order to free up any memory\u001b[39;00m\n\u001b[0;32m    358\u001b[0m         \u001b[38;5;66;03m# that may be referenced by them; after a call has happened,\u001b[39;00m\n\u001b[0;32m    359\u001b[0m         \u001b[38;5;66;03m# there's no need to keep a reference to them\u001b[39;00m\n\u001b[0;32m    360\u001b[0m         \u001b[38;5;28mself\u001b[39m\u001b[38;5;241m.\u001b[39margs \u001b[38;5;241m=\u001b[39m \u001b[38;5;28;01mNone\u001b[39;00m\n",
      "File \u001b[1;32mc:\\Users\\soham\\anaconda3\\envs\\echodataflow\\lib\\site-packages\\prefect\\client\\utilities.py:51\u001b[0m, in \u001b[0;36minject_client.<locals>.with_injected_client\u001b[1;34m(*args, **kwargs)\u001b[0m\n\u001b[0;32m     49\u001b[0m \u001b[38;5;28;01masync\u001b[39;00m \u001b[38;5;28;01mwith\u001b[39;00m client_context \u001b[38;5;28;01mas\u001b[39;00m new_client:\n\u001b[0;32m     50\u001b[0m     kwargs\u001b[38;5;241m.\u001b[39msetdefault(\u001b[38;5;124m\"\u001b[39m\u001b[38;5;124mclient\u001b[39m\u001b[38;5;124m\"\u001b[39m, new_client \u001b[38;5;129;01mor\u001b[39;00m client)\n\u001b[1;32m---> 51\u001b[0m     \u001b[38;5;28;01mreturn\u001b[39;00m \u001b[38;5;28;01mawait\u001b[39;00m fn(\u001b[38;5;241m*\u001b[39margs, \u001b[38;5;241m*\u001b[39m\u001b[38;5;241m*\u001b[39mkwargs)\n",
      "File \u001b[1;32mc:\\Users\\soham\\anaconda3\\envs\\echodataflow\\lib\\site-packages\\prefect\\engine.py:386\u001b[0m, in \u001b[0;36mcreate_then_begin_flow_run\u001b[1;34m(flow, parameters, wait_for, return_type, client, user_thread)\u001b[0m\n\u001b[0;32m    384\u001b[0m     \u001b[38;5;28;01mreturn\u001b[39;00m state\n\u001b[0;32m    385\u001b[0m \u001b[38;5;28;01melif\u001b[39;00m return_type \u001b[38;5;241m==\u001b[39m \u001b[38;5;124m\"\u001b[39m\u001b[38;5;124mresult\u001b[39m\u001b[38;5;124m\"\u001b[39m:\n\u001b[1;32m--> 386\u001b[0m     \u001b[38;5;28;01mreturn\u001b[39;00m \u001b[38;5;28;01mawait\u001b[39;00m state\u001b[38;5;241m.\u001b[39mresult(fetch\u001b[38;5;241m=\u001b[39m\u001b[38;5;28;01mTrue\u001b[39;00m)\n\u001b[0;32m    387\u001b[0m \u001b[38;5;28;01melse\u001b[39;00m:\n\u001b[0;32m    388\u001b[0m     \u001b[38;5;28;01mraise\u001b[39;00m \u001b[38;5;167;01mValueError\u001b[39;00m(\u001b[38;5;124mf\u001b[39m\u001b[38;5;124m\"\u001b[39m\u001b[38;5;124mInvalid return type for flow engine \u001b[39m\u001b[38;5;132;01m{\u001b[39;00mreturn_type\u001b[38;5;132;01m!r}\u001b[39;00m\u001b[38;5;124m.\u001b[39m\u001b[38;5;124m\"\u001b[39m)\n",
      "File \u001b[1;32mc:\\Users\\soham\\anaconda3\\envs\\echodataflow\\lib\\site-packages\\prefect\\states.py:91\u001b[0m, in \u001b[0;36m_get_state_result\u001b[1;34m(state, raise_on_failure)\u001b[0m\n\u001b[0;32m     84\u001b[0m     \u001b[38;5;28;01mraise\u001b[39;00m UnfinishedRun(\n\u001b[0;32m     85\u001b[0m         \u001b[38;5;124mf\u001b[39m\u001b[38;5;124m\"\u001b[39m\u001b[38;5;124mRun is in \u001b[39m\u001b[38;5;132;01m{\u001b[39;00mstate\u001b[38;5;241m.\u001b[39mtype\u001b[38;5;241m.\u001b[39mname\u001b[38;5;132;01m}\u001b[39;00m\u001b[38;5;124m state, its result is not available.\u001b[39m\u001b[38;5;124m\"\u001b[39m\n\u001b[0;32m     86\u001b[0m     )\n\u001b[0;32m     88\u001b[0m \u001b[38;5;28;01mif\u001b[39;00m raise_on_failure \u001b[38;5;129;01mand\u001b[39;00m (\n\u001b[0;32m     89\u001b[0m     state\u001b[38;5;241m.\u001b[39mis_crashed() \u001b[38;5;129;01mor\u001b[39;00m state\u001b[38;5;241m.\u001b[39mis_failed() \u001b[38;5;129;01mor\u001b[39;00m state\u001b[38;5;241m.\u001b[39mis_cancelled()\n\u001b[0;32m     90\u001b[0m ):\n\u001b[1;32m---> 91\u001b[0m     \u001b[38;5;28;01mraise\u001b[39;00m \u001b[38;5;28;01mawait\u001b[39;00m get_state_exception(state)\n\u001b[0;32m     93\u001b[0m \u001b[38;5;28;01mif\u001b[39;00m \u001b[38;5;28misinstance\u001b[39m(state\u001b[38;5;241m.\u001b[39mdata, DataDocument):\n\u001b[0;32m     94\u001b[0m     result \u001b[38;5;241m=\u001b[39m result_from_state_with_data_document(\n\u001b[0;32m     95\u001b[0m         state, raise_on_failure\u001b[38;5;241m=\u001b[39mraise_on_failure\n\u001b[0;32m     96\u001b[0m     )\n",
      "File \u001b[1;32mc:\\Users\\soham\\anaconda3\\envs\\echodataflow\\lib\\site-packages\\prefect\\engine.py:841\u001b[0m, in \u001b[0;36morchestrate_flow_run\u001b[1;34m(flow, flow_run, parameters, wait_for, interruptible, client, partial_flow_run_context, user_thread)\u001b[0m\n\u001b[0;32m    836\u001b[0m         \u001b[38;5;28;01melse\u001b[39;00m:\n\u001b[0;32m    837\u001b[0m             from_async\u001b[38;5;241m.\u001b[39mcall_soon_in_new_thread(\n\u001b[0;32m    838\u001b[0m                 flow_call, timeout\u001b[38;5;241m=\u001b[39mflow\u001b[38;5;241m.\u001b[39mtimeout_seconds\n\u001b[0;32m    839\u001b[0m             )\n\u001b[1;32m--> 841\u001b[0m         result \u001b[38;5;241m=\u001b[39m \u001b[38;5;28;01mawait\u001b[39;00m flow_call\u001b[38;5;241m.\u001b[39maresult()\n\u001b[0;32m    843\u001b[0m         waited_for_task_runs \u001b[38;5;241m=\u001b[39m \u001b[38;5;28;01mawait\u001b[39;00m wait_for_task_runs_and_report_crashes(\n\u001b[0;32m    844\u001b[0m             flow_run_context\u001b[38;5;241m.\u001b[39mtask_run_futures, client\u001b[38;5;241m=\u001b[39mclient\n\u001b[0;32m    845\u001b[0m         )\n\u001b[0;32m    846\u001b[0m \u001b[38;5;28;01mexcept\u001b[39;00m PausedRun \u001b[38;5;28;01mas\u001b[39;00m exc:\n\u001b[0;32m    847\u001b[0m     \u001b[38;5;66;03m# could get raised either via utility or by returning Paused from a task run\u001b[39;00m\n\u001b[0;32m    848\u001b[0m     \u001b[38;5;66;03m# if a task run pauses, we set its state as the flow's state\u001b[39;00m\n\u001b[0;32m    849\u001b[0m     \u001b[38;5;66;03m# to preserve reschedule and timeout behavior\u001b[39;00m\n",
      "File \u001b[1;32mc:\\Users\\soham\\anaconda3\\envs\\echodataflow\\lib\\site-packages\\prefect\\_internal\\concurrency\\calls.py:293\u001b[0m, in \u001b[0;36mCall.aresult\u001b[1;34m(self)\u001b[0m\n\u001b[0;32m    287\u001b[0m \u001b[38;5;250m\u001b[39m\u001b[38;5;124;03m\"\"\"\u001b[39;00m\n\u001b[0;32m    288\u001b[0m \u001b[38;5;124;03mWait for the result of the call.\u001b[39;00m\n\u001b[0;32m    289\u001b[0m \n\u001b[0;32m    290\u001b[0m \u001b[38;5;124;03mFor use from asynchronous contexts.\u001b[39;00m\n\u001b[0;32m    291\u001b[0m \u001b[38;5;124;03m\"\"\"\u001b[39;00m\n\u001b[0;32m    292\u001b[0m \u001b[38;5;28;01mtry\u001b[39;00m:\n\u001b[1;32m--> 293\u001b[0m     \u001b[38;5;28;01mreturn\u001b[39;00m \u001b[38;5;28;01mawait\u001b[39;00m asyncio\u001b[38;5;241m.\u001b[39mwrap_future(\u001b[38;5;28mself\u001b[39m\u001b[38;5;241m.\u001b[39mfuture)\n\u001b[0;32m    294\u001b[0m \u001b[38;5;28;01mexcept\u001b[39;00m asyncio\u001b[38;5;241m.\u001b[39mCancelledError \u001b[38;5;28;01mas\u001b[39;00m exc:\n\u001b[0;32m    295\u001b[0m     \u001b[38;5;28;01mraise\u001b[39;00m CancelledError() \u001b[38;5;28;01mfrom\u001b[39;00m \u001b[38;5;21;01mexc\u001b[39;00m\n",
      "File \u001b[1;32mc:\\Users\\soham\\anaconda3\\envs\\echodataflow\\lib\\asyncio\\futures.py:285\u001b[0m, in \u001b[0;36mFuture.__await__\u001b[1;34m(self)\u001b[0m\n\u001b[0;32m    283\u001b[0m \u001b[38;5;28;01mif\u001b[39;00m \u001b[38;5;129;01mnot\u001b[39;00m \u001b[38;5;28mself\u001b[39m\u001b[38;5;241m.\u001b[39mdone():\n\u001b[0;32m    284\u001b[0m     \u001b[38;5;28mself\u001b[39m\u001b[38;5;241m.\u001b[39m_asyncio_future_blocking \u001b[38;5;241m=\u001b[39m \u001b[38;5;28;01mTrue\u001b[39;00m\n\u001b[1;32m--> 285\u001b[0m     \u001b[38;5;28;01myield\u001b[39;00m \u001b[38;5;28mself\u001b[39m  \u001b[38;5;66;03m# This tells Task to wait for completion.\u001b[39;00m\n\u001b[0;32m    286\u001b[0m \u001b[38;5;28;01mif\u001b[39;00m \u001b[38;5;129;01mnot\u001b[39;00m \u001b[38;5;28mself\u001b[39m\u001b[38;5;241m.\u001b[39mdone():\n\u001b[0;32m    287\u001b[0m     \u001b[38;5;28;01mraise\u001b[39;00m \u001b[38;5;167;01mRuntimeError\u001b[39;00m(\u001b[38;5;124m\"\u001b[39m\u001b[38;5;124mawait wasn\u001b[39m\u001b[38;5;124m'\u001b[39m\u001b[38;5;124mt used with future\u001b[39m\u001b[38;5;124m\"\u001b[39m)\n",
      "File \u001b[1;32mc:\\Users\\soham\\anaconda3\\envs\\echodataflow\\lib\\asyncio\\tasks.py:304\u001b[0m, in \u001b[0;36mTask.__wakeup\u001b[1;34m(self, future)\u001b[0m\n\u001b[0;32m    302\u001b[0m \u001b[38;5;28;01mdef\u001b[39;00m \u001b[38;5;21m__wakeup\u001b[39m(\u001b[38;5;28mself\u001b[39m, future):\n\u001b[0;32m    303\u001b[0m     \u001b[38;5;28;01mtry\u001b[39;00m:\n\u001b[1;32m--> 304\u001b[0m         \u001b[43mfuture\u001b[49m\u001b[38;5;241;43m.\u001b[39;49m\u001b[43mresult\u001b[49m\u001b[43m(\u001b[49m\u001b[43m)\u001b[49m\n\u001b[0;32m    305\u001b[0m     \u001b[38;5;28;01mexcept\u001b[39;00m \u001b[38;5;167;01mBaseException\u001b[39;00m \u001b[38;5;28;01mas\u001b[39;00m exc:\n\u001b[0;32m    306\u001b[0m         \u001b[38;5;66;03m# This may also be a cancellation.\u001b[39;00m\n\u001b[0;32m    307\u001b[0m         \u001b[38;5;28mself\u001b[39m\u001b[38;5;241m.\u001b[39m__step(exc)\n",
      "File \u001b[1;32mc:\\Users\\soham\\anaconda3\\envs\\echodataflow\\lib\\asyncio\\futures.py:201\u001b[0m, in \u001b[0;36mFuture.result\u001b[1;34m(self)\u001b[0m\n\u001b[0;32m    199\u001b[0m \u001b[38;5;28mself\u001b[39m\u001b[38;5;241m.\u001b[39m__log_traceback \u001b[38;5;241m=\u001b[39m \u001b[38;5;28;01mFalse\u001b[39;00m\n\u001b[0;32m    200\u001b[0m \u001b[38;5;28;01mif\u001b[39;00m \u001b[38;5;28mself\u001b[39m\u001b[38;5;241m.\u001b[39m_exception \u001b[38;5;129;01mis\u001b[39;00m \u001b[38;5;129;01mnot\u001b[39;00m \u001b[38;5;28;01mNone\u001b[39;00m:\n\u001b[1;32m--> 201\u001b[0m     \u001b[38;5;28;01mraise\u001b[39;00m \u001b[38;5;28mself\u001b[39m\u001b[38;5;241m.\u001b[39m_exception\u001b[38;5;241m.\u001b[39mwith_traceback(\u001b[38;5;28mself\u001b[39m\u001b[38;5;241m.\u001b[39m_exception_tb)\n\u001b[0;32m    202\u001b[0m \u001b[38;5;28;01mreturn\u001b[39;00m \u001b[38;5;28mself\u001b[39m\u001b[38;5;241m.\u001b[39m_result\n",
      "File \u001b[1;32mc:\\Users\\soham\\anaconda3\\envs\\echodataflow\\lib\\site-packages\\prefect\\_internal\\concurrency\\calls.py:318\u001b[0m, in \u001b[0;36mCall._run_sync\u001b[1;34m(***failed resolving arguments***)\u001b[0m\n\u001b[0;32m    316\u001b[0m \u001b[38;5;28;01mwith\u001b[39;00m \u001b[38;5;28mself\u001b[39m\u001b[38;5;241m.\u001b[39mfuture\u001b[38;5;241m.\u001b[39menforce_sync_deadline() \u001b[38;5;28;01mas\u001b[39;00m cancel_scope:\n\u001b[0;32m    317\u001b[0m     \u001b[38;5;28;01mtry\u001b[39;00m:\n\u001b[1;32m--> 318\u001b[0m         result \u001b[38;5;241m=\u001b[39m \u001b[38;5;28mself\u001b[39m\u001b[38;5;241m.\u001b[39mfn(\u001b[38;5;241m*\u001b[39m\u001b[38;5;28mself\u001b[39m\u001b[38;5;241m.\u001b[39margs, \u001b[38;5;241m*\u001b[39m\u001b[38;5;241m*\u001b[39m\u001b[38;5;28mself\u001b[39m\u001b[38;5;241m.\u001b[39mkwargs)\n\u001b[0;32m    319\u001b[0m     \u001b[38;5;28;01mfinally\u001b[39;00m:\n\u001b[0;32m    320\u001b[0m         \u001b[38;5;66;03m# Forget this call's arguments in order to free up any memory\u001b[39;00m\n\u001b[0;32m    321\u001b[0m         \u001b[38;5;66;03m# that may be referenced by them; after a call has happened,\u001b[39;00m\n\u001b[0;32m    322\u001b[0m         \u001b[38;5;66;03m# there's no need to keep a reference to them\u001b[39;00m\n\u001b[0;32m    323\u001b[0m         \u001b[38;5;28mself\u001b[39m\u001b[38;5;241m.\u001b[39margs \u001b[38;5;241m=\u001b[39m \u001b[38;5;28;01mNone\u001b[39;00m\n",
      "File \u001b[1;32mc:\\Users\\soham\\anaconda3\\envs\\echodataflow\\lib\\site-packages\\echodataflow\\stages\\echodataflow_trigger.py:170\u001b[0m, in \u001b[0;36mechodataflow_trigger\u001b[1;34m(dataset_config, pipeline_config, logging_config, storage_options, options, json_data_path)\u001b[0m\n\u001b[0;32m    166\u001b[0m Singleton_Echodataflow(log_file\u001b[38;5;241m=\u001b[39mlogging_config_dict,\n\u001b[0;32m    167\u001b[0m                    pipeline\u001b[38;5;241m=\u001b[39mpipeline, dataset\u001b[38;5;241m=\u001b[39mdataset)\n\u001b[0;32m    169\u001b[0m \u001b[38;5;28mprint\u001b[39m(\u001b[38;5;124m\"\u001b[39m\u001b[38;5;130;01m\\n\u001b[39;00m\u001b[38;5;124mReading Configutations\u001b[39m\u001b[38;5;124m\"\u001b[39m)\n\u001b[1;32m--> 170\u001b[0m \u001b[38;5;28;01mreturn\u001b[39;00m \u001b[43minit_flow\u001b[49m\u001b[43m(\u001b[49m\u001b[43mconfig\u001b[49m\u001b[38;5;241;43m=\u001b[39;49m\u001b[43mdataset\u001b[49m\u001b[43m,\u001b[49m\u001b[43m \u001b[49m\u001b[43mpipeline\u001b[49m\u001b[38;5;241;43m=\u001b[39;49m\u001b[43mpipeline\u001b[49m\u001b[43m,\u001b[49m\u001b[43m \u001b[49m\u001b[43mjson_data_path\u001b[49m\u001b[38;5;241;43m=\u001b[39;49m\u001b[43mjson_data_path\u001b[49m\u001b[43m)\u001b[49m\n",
      "File \u001b[1;32mc:\\Users\\soham\\anaconda3\\envs\\echodataflow\\lib\\site-packages\\prefect\\flows.py:1097\u001b[0m, in \u001b[0;36mFlow.__call__\u001b[1;34m(self, return_state, wait_for, *args, **kwargs)\u001b[0m\n\u001b[0;32m   1092\u001b[0m \u001b[38;5;28;01mif\u001b[39;00m task_viz_tracker:\n\u001b[0;32m   1093\u001b[0m     \u001b[38;5;66;03m# this is a subflow, for now return a single task and do not go further\u001b[39;00m\n\u001b[0;32m   1094\u001b[0m     \u001b[38;5;66;03m# we can add support for exploring subflows for tasks in the future.\u001b[39;00m\n\u001b[0;32m   1095\u001b[0m     \u001b[38;5;28;01mreturn\u001b[39;00m track_viz_task(\u001b[38;5;28mself\u001b[39m\u001b[38;5;241m.\u001b[39misasync, \u001b[38;5;28mself\u001b[39m\u001b[38;5;241m.\u001b[39mname, parameters)\n\u001b[1;32m-> 1097\u001b[0m \u001b[38;5;28;01mreturn\u001b[39;00m \u001b[43menter_flow_run_engine_from_flow_call\u001b[49m\u001b[43m(\u001b[49m\n\u001b[0;32m   1098\u001b[0m \u001b[43m    \u001b[49m\u001b[38;5;28;43mself\u001b[39;49m\u001b[43m,\u001b[49m\n\u001b[0;32m   1099\u001b[0m \u001b[43m    \u001b[49m\u001b[43mparameters\u001b[49m\u001b[43m,\u001b[49m\n\u001b[0;32m   1100\u001b[0m \u001b[43m    \u001b[49m\u001b[43mwait_for\u001b[49m\u001b[38;5;241;43m=\u001b[39;49m\u001b[43mwait_for\u001b[49m\u001b[43m,\u001b[49m\n\u001b[0;32m   1101\u001b[0m \u001b[43m    \u001b[49m\u001b[43mreturn_type\u001b[49m\u001b[38;5;241;43m=\u001b[39;49m\u001b[43mreturn_type\u001b[49m\u001b[43m,\u001b[49m\n\u001b[0;32m   1102\u001b[0m \u001b[43m\u001b[49m\u001b[43m)\u001b[49m\n",
      "File \u001b[1;32mc:\\Users\\soham\\anaconda3\\envs\\echodataflow\\lib\\site-packages\\prefect\\engine.py:283\u001b[0m, in \u001b[0;36menter_flow_run_engine_from_flow_call\u001b[1;34m(flow, parameters, wait_for, return_type)\u001b[0m\n\u001b[0;32m    276\u001b[0m     retval \u001b[38;5;241m=\u001b[39m from_async\u001b[38;5;241m.\u001b[39mwait_for_call_in_loop_thread(\n\u001b[0;32m    277\u001b[0m         begin_run,\n\u001b[0;32m    278\u001b[0m         done_callbacks\u001b[38;5;241m=\u001b[39mdone_callbacks,\n\u001b[0;32m    279\u001b[0m         contexts\u001b[38;5;241m=\u001b[39mcontexts,\n\u001b[0;32m    280\u001b[0m     )\n\u001b[0;32m    282\u001b[0m \u001b[38;5;28;01melse\u001b[39;00m:\n\u001b[1;32m--> 283\u001b[0m     retval \u001b[38;5;241m=\u001b[39m \u001b[43mfrom_sync\u001b[49m\u001b[38;5;241;43m.\u001b[39;49m\u001b[43mwait_for_call_in_loop_thread\u001b[49m\u001b[43m(\u001b[49m\n\u001b[0;32m    284\u001b[0m \u001b[43m        \u001b[49m\u001b[43mbegin_run\u001b[49m\u001b[43m,\u001b[49m\n\u001b[0;32m    285\u001b[0m \u001b[43m        \u001b[49m\u001b[43mdone_callbacks\u001b[49m\u001b[38;5;241;43m=\u001b[39;49m\u001b[43mdone_callbacks\u001b[49m\u001b[43m,\u001b[49m\n\u001b[0;32m    286\u001b[0m \u001b[43m        \u001b[49m\u001b[43mcontexts\u001b[49m\u001b[38;5;241;43m=\u001b[39;49m\u001b[43mcontexts\u001b[49m\u001b[43m,\u001b[49m\n\u001b[0;32m    287\u001b[0m \u001b[43m    \u001b[49m\u001b[43m)\u001b[49m\n\u001b[0;32m    289\u001b[0m \u001b[38;5;28;01mreturn\u001b[39;00m retval\n",
      "File \u001b[1;32mc:\\Users\\soham\\anaconda3\\envs\\echodataflow\\lib\\site-packages\\prefect\\_internal\\concurrency\\api.py:243\u001b[0m, in \u001b[0;36mfrom_sync.wait_for_call_in_loop_thread\u001b[1;34m(_from_sync__call, timeout, done_callbacks, contexts)\u001b[0m\n\u001b[0;32m    241\u001b[0m     stack\u001b[38;5;241m.\u001b[39menter_context(context)\n\u001b[0;32m    242\u001b[0m waiter\u001b[38;5;241m.\u001b[39mwait()\n\u001b[1;32m--> 243\u001b[0m \u001b[38;5;28;01mreturn\u001b[39;00m \u001b[43mcall\u001b[49m\u001b[38;5;241;43m.\u001b[39;49m\u001b[43mresult\u001b[49m\u001b[43m(\u001b[49m\u001b[43m)\u001b[49m\n",
      "File \u001b[1;32mc:\\Users\\soham\\anaconda3\\envs\\echodataflow\\lib\\site-packages\\prefect\\_internal\\concurrency\\calls.py:284\u001b[0m, in \u001b[0;36mCall.result\u001b[1;34m(self, timeout)\u001b[0m\n\u001b[0;32m    278\u001b[0m \u001b[38;5;28;01mdef\u001b[39;00m \u001b[38;5;21mresult\u001b[39m(\u001b[38;5;28mself\u001b[39m, timeout: Optional[\u001b[38;5;28mfloat\u001b[39m] \u001b[38;5;241m=\u001b[39m \u001b[38;5;28;01mNone\u001b[39;00m) \u001b[38;5;241m-\u001b[39m\u001b[38;5;241m>\u001b[39m T:\n\u001b[0;32m    279\u001b[0m \u001b[38;5;250m    \u001b[39m\u001b[38;5;124;03m\"\"\"\u001b[39;00m\n\u001b[0;32m    280\u001b[0m \u001b[38;5;124;03m    Wait for the result of the call.\u001b[39;00m\n\u001b[0;32m    281\u001b[0m \n\u001b[0;32m    282\u001b[0m \u001b[38;5;124;03m    Not safe for use from asynchronous contexts.\u001b[39;00m\n\u001b[0;32m    283\u001b[0m \u001b[38;5;124;03m    \"\"\"\u001b[39;00m\n\u001b[1;32m--> 284\u001b[0m     \u001b[38;5;28;01mreturn\u001b[39;00m \u001b[38;5;28;43mself\u001b[39;49m\u001b[38;5;241;43m.\u001b[39;49m\u001b[43mfuture\u001b[49m\u001b[38;5;241;43m.\u001b[39;49m\u001b[43mresult\u001b[49m\u001b[43m(\u001b[49m\u001b[43mtimeout\u001b[49m\u001b[38;5;241;43m=\u001b[39;49m\u001b[43mtimeout\u001b[49m\u001b[43m)\u001b[49m\n",
      "File \u001b[1;32mc:\\Users\\soham\\anaconda3\\envs\\echodataflow\\lib\\site-packages\\prefect\\_internal\\concurrency\\calls.py:168\u001b[0m, in \u001b[0;36mFuture.result\u001b[1;34m(self, timeout)\u001b[0m\n\u001b[0;32m    166\u001b[0m     \u001b[38;5;28;01mraise\u001b[39;00m CancelledError()\n\u001b[0;32m    167\u001b[0m \u001b[38;5;28;01melif\u001b[39;00m \u001b[38;5;28mself\u001b[39m\u001b[38;5;241m.\u001b[39m_state \u001b[38;5;241m==\u001b[39m FINISHED:\n\u001b[1;32m--> 168\u001b[0m     \u001b[38;5;28;01mreturn\u001b[39;00m \u001b[38;5;28;43mself\u001b[39;49m\u001b[38;5;241;43m.\u001b[39;49m\u001b[43m__get_result\u001b[49m\u001b[43m(\u001b[49m\u001b[43m)\u001b[49m\n\u001b[0;32m    170\u001b[0m \u001b[38;5;28mself\u001b[39m\u001b[38;5;241m.\u001b[39m_condition\u001b[38;5;241m.\u001b[39mwait(timeout)\n\u001b[0;32m    172\u001b[0m \u001b[38;5;28;01mif\u001b[39;00m \u001b[38;5;28mself\u001b[39m\u001b[38;5;241m.\u001b[39m_state \u001b[38;5;129;01min\u001b[39;00m [CANCELLED, CANCELLED_AND_NOTIFIED]:\n\u001b[0;32m    173\u001b[0m     \u001b[38;5;66;03m# Raise Prefect cancelled error instead of\u001b[39;00m\n\u001b[0;32m    174\u001b[0m     \u001b[38;5;66;03m# `concurrent.futures._base.CancelledError`\u001b[39;00m\n",
      "File \u001b[1;32mc:\\Users\\soham\\anaconda3\\envs\\echodataflow\\lib\\concurrent\\futures\\_base.py:403\u001b[0m, in \u001b[0;36mFuture.__get_result\u001b[1;34m(self)\u001b[0m\n\u001b[0;32m    401\u001b[0m \u001b[38;5;28;01mif\u001b[39;00m \u001b[38;5;28mself\u001b[39m\u001b[38;5;241m.\u001b[39m_exception:\n\u001b[0;32m    402\u001b[0m     \u001b[38;5;28;01mtry\u001b[39;00m:\n\u001b[1;32m--> 403\u001b[0m         \u001b[38;5;28;01mraise\u001b[39;00m \u001b[38;5;28mself\u001b[39m\u001b[38;5;241m.\u001b[39m_exception\n\u001b[0;32m    404\u001b[0m     \u001b[38;5;28;01mfinally\u001b[39;00m:\n\u001b[0;32m    405\u001b[0m         \u001b[38;5;66;03m# Break a reference cycle with the exception in self._exception\u001b[39;00m\n\u001b[0;32m    406\u001b[0m         \u001b[38;5;28mself\u001b[39m \u001b[38;5;241m=\u001b[39m \u001b[38;5;28;01mNone\u001b[39;00m\n",
      "File \u001b[1;32mc:\\Users\\soham\\anaconda3\\envs\\echodataflow\\lib\\site-packages\\prefect\\_internal\\concurrency\\calls.py:355\u001b[0m, in \u001b[0;36mCall._run_async\u001b[1;34m(***failed resolving arguments***)\u001b[0m\n\u001b[0;32m    353\u001b[0m \u001b[38;5;28;01mwith\u001b[39;00m \u001b[38;5;28mself\u001b[39m\u001b[38;5;241m.\u001b[39mfuture\u001b[38;5;241m.\u001b[39menforce_async_deadline() \u001b[38;5;28;01mas\u001b[39;00m cancel_scope:\n\u001b[0;32m    354\u001b[0m     \u001b[38;5;28;01mtry\u001b[39;00m:\n\u001b[1;32m--> 355\u001b[0m         result \u001b[38;5;241m=\u001b[39m \u001b[38;5;28;01mawait\u001b[39;00m coro\n\u001b[0;32m    356\u001b[0m     \u001b[38;5;28;01mfinally\u001b[39;00m:\n\u001b[0;32m    357\u001b[0m         \u001b[38;5;66;03m# Forget this call's arguments in order to free up any memory\u001b[39;00m\n\u001b[0;32m    358\u001b[0m         \u001b[38;5;66;03m# that may be referenced by them; after a call has happened,\u001b[39;00m\n\u001b[0;32m    359\u001b[0m         \u001b[38;5;66;03m# there's no need to keep a reference to them\u001b[39;00m\n\u001b[0;32m    360\u001b[0m         \u001b[38;5;28mself\u001b[39m\u001b[38;5;241m.\u001b[39margs \u001b[38;5;241m=\u001b[39m \u001b[38;5;28;01mNone\u001b[39;00m\n",
      "File \u001b[1;32mc:\\Users\\soham\\anaconda3\\envs\\echodataflow\\lib\\site-packages\\prefect\\client\\utilities.py:51\u001b[0m, in \u001b[0;36minject_client.<locals>.with_injected_client\u001b[1;34m(*args, **kwargs)\u001b[0m\n\u001b[0;32m     49\u001b[0m \u001b[38;5;28;01masync\u001b[39;00m \u001b[38;5;28;01mwith\u001b[39;00m client_context \u001b[38;5;28;01mas\u001b[39;00m new_client:\n\u001b[0;32m     50\u001b[0m     kwargs\u001b[38;5;241m.\u001b[39msetdefault(\u001b[38;5;124m\"\u001b[39m\u001b[38;5;124mclient\u001b[39m\u001b[38;5;124m\"\u001b[39m, new_client \u001b[38;5;129;01mor\u001b[39;00m client)\n\u001b[1;32m---> 51\u001b[0m     \u001b[38;5;28;01mreturn\u001b[39;00m \u001b[38;5;28;01mawait\u001b[39;00m fn(\u001b[38;5;241m*\u001b[39margs, \u001b[38;5;241m*\u001b[39m\u001b[38;5;241m*\u001b[39mkwargs)\n",
      "File \u001b[1;32mc:\\Users\\soham\\anaconda3\\envs\\echodataflow\\lib\\site-packages\\prefect\\engine.py:725\u001b[0m, in \u001b[0;36mcreate_and_begin_subflow_run\u001b[1;34m(flow, parameters, wait_for, return_type, client, user_thread)\u001b[0m\n\u001b[0;32m    723\u001b[0m     \u001b[38;5;28;01mreturn\u001b[39;00m terminal_state\n\u001b[0;32m    724\u001b[0m \u001b[38;5;28;01melif\u001b[39;00m return_type \u001b[38;5;241m==\u001b[39m \u001b[38;5;124m\"\u001b[39m\u001b[38;5;124mresult\u001b[39m\u001b[38;5;124m\"\u001b[39m:\n\u001b[1;32m--> 725\u001b[0m     \u001b[38;5;28;01mreturn\u001b[39;00m \u001b[38;5;28;01mawait\u001b[39;00m terminal_state\u001b[38;5;241m.\u001b[39mresult(fetch\u001b[38;5;241m=\u001b[39m\u001b[38;5;28;01mTrue\u001b[39;00m)\n\u001b[0;32m    726\u001b[0m \u001b[38;5;28;01melse\u001b[39;00m:\n\u001b[0;32m    727\u001b[0m     \u001b[38;5;28;01mraise\u001b[39;00m \u001b[38;5;167;01mValueError\u001b[39;00m(\u001b[38;5;124mf\u001b[39m\u001b[38;5;124m\"\u001b[39m\u001b[38;5;124mInvalid return type for flow engine \u001b[39m\u001b[38;5;132;01m{\u001b[39;00mreturn_type\u001b[38;5;132;01m!r}\u001b[39;00m\u001b[38;5;124m.\u001b[39m\u001b[38;5;124m\"\u001b[39m)\n",
      "File \u001b[1;32mc:\\Users\\soham\\anaconda3\\envs\\echodataflow\\lib\\site-packages\\prefect\\states.py:91\u001b[0m, in \u001b[0;36m_get_state_result\u001b[1;34m(state, raise_on_failure)\u001b[0m\n\u001b[0;32m     84\u001b[0m     \u001b[38;5;28;01mraise\u001b[39;00m UnfinishedRun(\n\u001b[0;32m     85\u001b[0m         \u001b[38;5;124mf\u001b[39m\u001b[38;5;124m\"\u001b[39m\u001b[38;5;124mRun is in \u001b[39m\u001b[38;5;132;01m{\u001b[39;00mstate\u001b[38;5;241m.\u001b[39mtype\u001b[38;5;241m.\u001b[39mname\u001b[38;5;132;01m}\u001b[39;00m\u001b[38;5;124m state, its result is not available.\u001b[39m\u001b[38;5;124m\"\u001b[39m\n\u001b[0;32m     86\u001b[0m     )\n\u001b[0;32m     88\u001b[0m \u001b[38;5;28;01mif\u001b[39;00m raise_on_failure \u001b[38;5;129;01mand\u001b[39;00m (\n\u001b[0;32m     89\u001b[0m     state\u001b[38;5;241m.\u001b[39mis_crashed() \u001b[38;5;129;01mor\u001b[39;00m state\u001b[38;5;241m.\u001b[39mis_failed() \u001b[38;5;129;01mor\u001b[39;00m state\u001b[38;5;241m.\u001b[39mis_cancelled()\n\u001b[0;32m     90\u001b[0m ):\n\u001b[1;32m---> 91\u001b[0m     \u001b[38;5;28;01mraise\u001b[39;00m \u001b[38;5;28;01mawait\u001b[39;00m get_state_exception(state)\n\u001b[0;32m     93\u001b[0m \u001b[38;5;28;01mif\u001b[39;00m \u001b[38;5;28misinstance\u001b[39m(state\u001b[38;5;241m.\u001b[39mdata, DataDocument):\n\u001b[0;32m     94\u001b[0m     result \u001b[38;5;241m=\u001b[39m result_from_state_with_data_document(\n\u001b[0;32m     95\u001b[0m         state, raise_on_failure\u001b[38;5;241m=\u001b[39mraise_on_failure\n\u001b[0;32m     96\u001b[0m     )\n",
      "File \u001b[1;32mc:\\Users\\soham\\anaconda3\\envs\\echodataflow\\lib\\site-packages\\prefect\\engine.py:841\u001b[0m, in \u001b[0;36morchestrate_flow_run\u001b[1;34m(flow, flow_run, parameters, wait_for, interruptible, client, partial_flow_run_context, user_thread)\u001b[0m\n\u001b[0;32m    836\u001b[0m         \u001b[38;5;28;01melse\u001b[39;00m:\n\u001b[0;32m    837\u001b[0m             from_async\u001b[38;5;241m.\u001b[39mcall_soon_in_new_thread(\n\u001b[0;32m    838\u001b[0m                 flow_call, timeout\u001b[38;5;241m=\u001b[39mflow\u001b[38;5;241m.\u001b[39mtimeout_seconds\n\u001b[0;32m    839\u001b[0m             )\n\u001b[1;32m--> 841\u001b[0m         result \u001b[38;5;241m=\u001b[39m \u001b[38;5;28;01mawait\u001b[39;00m flow_call\u001b[38;5;241m.\u001b[39maresult()\n\u001b[0;32m    843\u001b[0m         waited_for_task_runs \u001b[38;5;241m=\u001b[39m \u001b[38;5;28;01mawait\u001b[39;00m wait_for_task_runs_and_report_crashes(\n\u001b[0;32m    844\u001b[0m             flow_run_context\u001b[38;5;241m.\u001b[39mtask_run_futures, client\u001b[38;5;241m=\u001b[39mclient\n\u001b[0;32m    845\u001b[0m         )\n\u001b[0;32m    846\u001b[0m \u001b[38;5;28;01mexcept\u001b[39;00m PausedRun \u001b[38;5;28;01mas\u001b[39;00m exc:\n\u001b[0;32m    847\u001b[0m     \u001b[38;5;66;03m# could get raised either via utility or by returning Paused from a task run\u001b[39;00m\n\u001b[0;32m    848\u001b[0m     \u001b[38;5;66;03m# if a task run pauses, we set its state as the flow's state\u001b[39;00m\n\u001b[0;32m    849\u001b[0m     \u001b[38;5;66;03m# to preserve reschedule and timeout behavior\u001b[39;00m\n",
      "File \u001b[1;32mc:\\Users\\soham\\anaconda3\\envs\\echodataflow\\lib\\site-packages\\prefect\\_internal\\concurrency\\calls.py:293\u001b[0m, in \u001b[0;36mCall.aresult\u001b[1;34m(self)\u001b[0m\n\u001b[0;32m    287\u001b[0m \u001b[38;5;250m\u001b[39m\u001b[38;5;124;03m\"\"\"\u001b[39;00m\n\u001b[0;32m    288\u001b[0m \u001b[38;5;124;03mWait for the result of the call.\u001b[39;00m\n\u001b[0;32m    289\u001b[0m \n\u001b[0;32m    290\u001b[0m \u001b[38;5;124;03mFor use from asynchronous contexts.\u001b[39;00m\n\u001b[0;32m    291\u001b[0m \u001b[38;5;124;03m\"\"\"\u001b[39;00m\n\u001b[0;32m    292\u001b[0m \u001b[38;5;28;01mtry\u001b[39;00m:\n\u001b[1;32m--> 293\u001b[0m     \u001b[38;5;28;01mreturn\u001b[39;00m \u001b[38;5;28;01mawait\u001b[39;00m asyncio\u001b[38;5;241m.\u001b[39mwrap_future(\u001b[38;5;28mself\u001b[39m\u001b[38;5;241m.\u001b[39mfuture)\n\u001b[0;32m    294\u001b[0m \u001b[38;5;28;01mexcept\u001b[39;00m asyncio\u001b[38;5;241m.\u001b[39mCancelledError \u001b[38;5;28;01mas\u001b[39;00m exc:\n\u001b[0;32m    295\u001b[0m     \u001b[38;5;28;01mraise\u001b[39;00m CancelledError() \u001b[38;5;28;01mfrom\u001b[39;00m \u001b[38;5;21;01mexc\u001b[39;00m\n",
      "File \u001b[1;32mc:\\Users\\soham\\anaconda3\\envs\\echodataflow\\lib\\asyncio\\futures.py:285\u001b[0m, in \u001b[0;36mFuture.__await__\u001b[1;34m(self)\u001b[0m\n\u001b[0;32m    283\u001b[0m \u001b[38;5;28;01mif\u001b[39;00m \u001b[38;5;129;01mnot\u001b[39;00m \u001b[38;5;28mself\u001b[39m\u001b[38;5;241m.\u001b[39mdone():\n\u001b[0;32m    284\u001b[0m     \u001b[38;5;28mself\u001b[39m\u001b[38;5;241m.\u001b[39m_asyncio_future_blocking \u001b[38;5;241m=\u001b[39m \u001b[38;5;28;01mTrue\u001b[39;00m\n\u001b[1;32m--> 285\u001b[0m     \u001b[38;5;28;01myield\u001b[39;00m \u001b[38;5;28mself\u001b[39m  \u001b[38;5;66;03m# This tells Task to wait for completion.\u001b[39;00m\n\u001b[0;32m    286\u001b[0m \u001b[38;5;28;01mif\u001b[39;00m \u001b[38;5;129;01mnot\u001b[39;00m \u001b[38;5;28mself\u001b[39m\u001b[38;5;241m.\u001b[39mdone():\n\u001b[0;32m    287\u001b[0m     \u001b[38;5;28;01mraise\u001b[39;00m \u001b[38;5;167;01mRuntimeError\u001b[39;00m(\u001b[38;5;124m\"\u001b[39m\u001b[38;5;124mawait wasn\u001b[39m\u001b[38;5;124m'\u001b[39m\u001b[38;5;124mt used with future\u001b[39m\u001b[38;5;124m\"\u001b[39m)\n",
      "File \u001b[1;32mc:\\Users\\soham\\anaconda3\\envs\\echodataflow\\lib\\asyncio\\tasks.py:304\u001b[0m, in \u001b[0;36mTask.__wakeup\u001b[1;34m(self, future)\u001b[0m\n\u001b[0;32m    302\u001b[0m \u001b[38;5;28;01mdef\u001b[39;00m \u001b[38;5;21m__wakeup\u001b[39m(\u001b[38;5;28mself\u001b[39m, future):\n\u001b[0;32m    303\u001b[0m     \u001b[38;5;28;01mtry\u001b[39;00m:\n\u001b[1;32m--> 304\u001b[0m         \u001b[43mfuture\u001b[49m\u001b[38;5;241;43m.\u001b[39;49m\u001b[43mresult\u001b[49m\u001b[43m(\u001b[49m\u001b[43m)\u001b[49m\n\u001b[0;32m    305\u001b[0m     \u001b[38;5;28;01mexcept\u001b[39;00m \u001b[38;5;167;01mBaseException\u001b[39;00m \u001b[38;5;28;01mas\u001b[39;00m exc:\n\u001b[0;32m    306\u001b[0m         \u001b[38;5;66;03m# This may also be a cancellation.\u001b[39;00m\n\u001b[0;32m    307\u001b[0m         \u001b[38;5;28mself\u001b[39m\u001b[38;5;241m.\u001b[39m__step(exc)\n",
      "File \u001b[1;32mc:\\Users\\soham\\anaconda3\\envs\\echodataflow\\lib\\asyncio\\futures.py:201\u001b[0m, in \u001b[0;36mFuture.result\u001b[1;34m(self)\u001b[0m\n\u001b[0;32m    199\u001b[0m \u001b[38;5;28mself\u001b[39m\u001b[38;5;241m.\u001b[39m__log_traceback \u001b[38;5;241m=\u001b[39m \u001b[38;5;28;01mFalse\u001b[39;00m\n\u001b[0;32m    200\u001b[0m \u001b[38;5;28;01mif\u001b[39;00m \u001b[38;5;28mself\u001b[39m\u001b[38;5;241m.\u001b[39m_exception \u001b[38;5;129;01mis\u001b[39;00m \u001b[38;5;129;01mnot\u001b[39;00m \u001b[38;5;28;01mNone\u001b[39;00m:\n\u001b[1;32m--> 201\u001b[0m     \u001b[38;5;28;01mraise\u001b[39;00m \u001b[38;5;28mself\u001b[39m\u001b[38;5;241m.\u001b[39m_exception\u001b[38;5;241m.\u001b[39mwith_traceback(\u001b[38;5;28mself\u001b[39m\u001b[38;5;241m.\u001b[39m_exception_tb)\n\u001b[0;32m    202\u001b[0m \u001b[38;5;28;01mreturn\u001b[39;00m \u001b[38;5;28mself\u001b[39m\u001b[38;5;241m.\u001b[39m_result\n",
      "File \u001b[1;32mc:\\Users\\soham\\anaconda3\\envs\\echodataflow\\lib\\site-packages\\prefect\\_internal\\concurrency\\calls.py:318\u001b[0m, in \u001b[0;36mCall._run_sync\u001b[1;34m(***failed resolving arguments***)\u001b[0m\n\u001b[0;32m    316\u001b[0m \u001b[38;5;28;01mwith\u001b[39;00m \u001b[38;5;28mself\u001b[39m\u001b[38;5;241m.\u001b[39mfuture\u001b[38;5;241m.\u001b[39menforce_sync_deadline() \u001b[38;5;28;01mas\u001b[39;00m cancel_scope:\n\u001b[0;32m    317\u001b[0m     \u001b[38;5;28;01mtry\u001b[39;00m:\n\u001b[1;32m--> 318\u001b[0m         result \u001b[38;5;241m=\u001b[39m \u001b[38;5;28mself\u001b[39m\u001b[38;5;241m.\u001b[39mfn(\u001b[38;5;241m*\u001b[39m\u001b[38;5;28mself\u001b[39m\u001b[38;5;241m.\u001b[39margs, \u001b[38;5;241m*\u001b[39m\u001b[38;5;241m*\u001b[39m\u001b[38;5;28mself\u001b[39m\u001b[38;5;241m.\u001b[39mkwargs)\n\u001b[0;32m    319\u001b[0m     \u001b[38;5;28;01mfinally\u001b[39;00m:\n\u001b[0;32m    320\u001b[0m         \u001b[38;5;66;03m# Forget this call's arguments in order to free up any memory\u001b[39;00m\n\u001b[0;32m    321\u001b[0m         \u001b[38;5;66;03m# that may be referenced by them; after a call has happened,\u001b[39;00m\n\u001b[0;32m    322\u001b[0m         \u001b[38;5;66;03m# there's no need to keep a reference to them\u001b[39;00m\n\u001b[0;32m    323\u001b[0m         \u001b[38;5;28mself\u001b[39m\u001b[38;5;241m.\u001b[39margs \u001b[38;5;241m=\u001b[39m \u001b[38;5;28;01mNone\u001b[39;00m\n",
      "File \u001b[1;32mc:\\Users\\soham\\anaconda3\\envs\\echodataflow\\lib\\site-packages\\echodataflow\\aspects\\echodataflow_aspect.py:97\u001b[0m, in \u001b[0;36mechodataflow.<locals>.decorator.<locals>.wrapper\u001b[1;34m(*args, **kwargs)\u001b[0m\n\u001b[0;32m     95\u001b[0m     \u001b[38;5;28;01mreturn\u001b[39;00m {\u001b[38;5;124m'\u001b[39m\u001b[38;5;124merror\u001b[39m\u001b[38;5;124m'\u001b[39m: \u001b[38;5;28;01mTrue\u001b[39;00m, \u001b[38;5;124m'\u001b[39m\u001b[38;5;124merror_desc\u001b[39m\u001b[38;5;124m'\u001b[39m: e}\n\u001b[0;32m     96\u001b[0m \u001b[38;5;28;01melse\u001b[39;00m:\n\u001b[1;32m---> 97\u001b[0m     \u001b[38;5;28;01mraise\u001b[39;00m e\n",
      "File \u001b[1;32mc:\\Users\\soham\\anaconda3\\envs\\echodataflow\\lib\\site-packages\\echodataflow\\aspects\\echodataflow_aspect.py:90\u001b[0m, in \u001b[0;36mechodataflow.<locals>.decorator.<locals>.wrapper\u001b[1;34m(*args, **kwargs)\u001b[0m\n\u001b[0;32m     87\u001b[0m \u001b[38;5;28;01mtry\u001b[39;00m:\n\u001b[0;32m     88\u001b[0m     before_function_call(\n\u001b[0;32m     89\u001b[0m         gea, \u001b[38;5;28mtype\u001b[39m, processing_stage, \u001b[38;5;241m*\u001b[39margs, \u001b[38;5;241m*\u001b[39m\u001b[38;5;241m*\u001b[39mkwargs)\n\u001b[1;32m---> 90\u001b[0m     result \u001b[38;5;241m=\u001b[39m func(\u001b[38;5;241m*\u001b[39margs, \u001b[38;5;241m*\u001b[39m\u001b[38;5;241m*\u001b[39mkwargs)\n\u001b[0;32m     91\u001b[0m     after_function_call(gea, \u001b[38;5;241m*\u001b[39margs, \u001b[38;5;241m*\u001b[39m\u001b[38;5;241m*\u001b[39mkwargs)\n\u001b[0;32m     92\u001b[0m     \u001b[38;5;28;01mreturn\u001b[39;00m result\n",
      "File \u001b[1;32mc:\\Users\\soham\\anaconda3\\envs\\echodataflow\\lib\\site-packages\\echodataflow\\stages\\subflows\\initialization_flow.py:74\u001b[0m, in \u001b[0;36minit_flow\u001b[1;34m(pipeline, config, json_data_path)\u001b[0m\n\u001b[0;32m     72\u001b[0m         file_dicts \u001b[38;5;241m=\u001b[39m parse_raw_paths(all_raw_files\u001b[38;5;241m=\u001b[39mtotal_files, config\u001b[38;5;241m=\u001b[39mconfig)\n\u001b[0;32m     73\u001b[0m         \u001b[38;5;28mprint\u001b[39m(file_dicts)\n\u001b[1;32m---> 74\u001b[0m     data \u001b[38;5;241m=\u001b[39m \u001b[43mclub_raw_files\u001b[49m\u001b[43m(\u001b[49m\n\u001b[0;32m     75\u001b[0m \u001b[43m        \u001b[49m\u001b[43mconfig\u001b[49m\u001b[38;5;241;43m=\u001b[39;49m\u001b[43mconfig\u001b[49m\u001b[43m,\u001b[49m\n\u001b[0;32m     76\u001b[0m \u001b[43m        \u001b[49m\u001b[43mraw_dicts\u001b[49m\u001b[38;5;241;43m=\u001b[39;49m\u001b[43mfile_dicts\u001b[49m\u001b[43m,\u001b[49m\n\u001b[0;32m     77\u001b[0m \u001b[43m        \u001b[49m\u001b[43mraw_url_file\u001b[49m\u001b[38;5;241;43m=\u001b[39;49m\u001b[43mconfig\u001b[49m\u001b[38;5;241;43m.\u001b[39;49m\u001b[43margs\u001b[49m\u001b[38;5;241;43m.\u001b[39;49m\u001b[43mraw_json_path\u001b[49m\u001b[43m,\u001b[49m\n\u001b[0;32m     78\u001b[0m \u001b[43m        \u001b[49m\u001b[43mjson_storage_options\u001b[49m\u001b[38;5;241;43m=\u001b[39;49m\u001b[43mconfig\u001b[49m\u001b[38;5;241;43m.\u001b[39;49m\u001b[43moutput\u001b[49m\u001b[38;5;241;43m.\u001b[39;49m\u001b[43mstorage_options_dict\u001b[49m\n\u001b[0;32m     79\u001b[0m \u001b[43m    \u001b[49m\u001b[43m)\u001b[49m\n\u001b[0;32m     80\u001b[0m \u001b[38;5;28;01melse\u001b[39;00m:\n\u001b[0;32m     81\u001b[0m     file_system \u001b[38;5;241m=\u001b[39m extract_fs(\n\u001b[0;32m     82\u001b[0m         json_data_path, storage_options\u001b[38;5;241m=\u001b[39mconfig\u001b[38;5;241m.\u001b[39margs\u001b[38;5;241m.\u001b[39mstorage_options_dict\n\u001b[0;32m     83\u001b[0m     )\n",
      "File \u001b[1;32mc:\\Users\\soham\\anaconda3\\envs\\echodataflow\\lib\\site-packages\\prefect\\tasks.py:549\u001b[0m, in \u001b[0;36mTask.__call__\u001b[1;34m(self, return_state, wait_for, *args, **kwargs)\u001b[0m\n\u001b[0;32m    544\u001b[0m \u001b[38;5;28;01mif\u001b[39;00m task_run_tracker:\n\u001b[0;32m    545\u001b[0m     \u001b[38;5;28;01mreturn\u001b[39;00m track_viz_task(\n\u001b[0;32m    546\u001b[0m         \u001b[38;5;28mself\u001b[39m\u001b[38;5;241m.\u001b[39misasync, \u001b[38;5;28mself\u001b[39m\u001b[38;5;241m.\u001b[39mname, parameters, \u001b[38;5;28mself\u001b[39m\u001b[38;5;241m.\u001b[39mviz_return_value\n\u001b[0;32m    547\u001b[0m     )\n\u001b[1;32m--> 549\u001b[0m \u001b[38;5;28;01mreturn\u001b[39;00m \u001b[43menter_task_run_engine\u001b[49m\u001b[43m(\u001b[49m\n\u001b[0;32m    550\u001b[0m \u001b[43m    \u001b[49m\u001b[38;5;28;43mself\u001b[39;49m\u001b[43m,\u001b[49m\n\u001b[0;32m    551\u001b[0m \u001b[43m    \u001b[49m\u001b[43mparameters\u001b[49m\u001b[38;5;241;43m=\u001b[39;49m\u001b[43mparameters\u001b[49m\u001b[43m,\u001b[49m\n\u001b[0;32m    552\u001b[0m \u001b[43m    \u001b[49m\u001b[43mwait_for\u001b[49m\u001b[38;5;241;43m=\u001b[39;49m\u001b[43mwait_for\u001b[49m\u001b[43m,\u001b[49m\n\u001b[0;32m    553\u001b[0m \u001b[43m    \u001b[49m\u001b[43mtask_runner\u001b[49m\u001b[38;5;241;43m=\u001b[39;49m\u001b[43mSequentialTaskRunner\u001b[49m\u001b[43m(\u001b[49m\u001b[43m)\u001b[49m\u001b[43m,\u001b[49m\n\u001b[0;32m    554\u001b[0m \u001b[43m    \u001b[49m\u001b[43mreturn_type\u001b[49m\u001b[38;5;241;43m=\u001b[39;49m\u001b[43mreturn_type\u001b[49m\u001b[43m,\u001b[49m\n\u001b[0;32m    555\u001b[0m \u001b[43m    \u001b[49m\u001b[43mmapped\u001b[49m\u001b[38;5;241;43m=\u001b[39;49m\u001b[38;5;28;43;01mFalse\u001b[39;49;00m\u001b[43m,\u001b[49m\n\u001b[0;32m    556\u001b[0m \u001b[43m\u001b[49m\u001b[43m)\u001b[49m\n",
      "File \u001b[1;32mc:\\Users\\soham\\anaconda3\\envs\\echodataflow\\lib\\site-packages\\prefect\\engine.py:1156\u001b[0m, in \u001b[0;36menter_task_run_engine\u001b[1;34m(task, parameters, wait_for, return_type, task_runner, mapped)\u001b[0m\n\u001b[0;32m   1154\u001b[0m     \u001b[38;5;28;01mreturn\u001b[39;00m from_async\u001b[38;5;241m.\u001b[39mwait_for_call_in_loop_thread(begin_run)\n\u001b[0;32m   1155\u001b[0m \u001b[38;5;28;01melse\u001b[39;00m:\n\u001b[1;32m-> 1156\u001b[0m     \u001b[38;5;28;01mreturn\u001b[39;00m \u001b[43mfrom_sync\u001b[49m\u001b[38;5;241;43m.\u001b[39;49m\u001b[43mwait_for_call_in_loop_thread\u001b[49m\u001b[43m(\u001b[49m\u001b[43mbegin_run\u001b[49m\u001b[43m)\u001b[49m\n",
      "File \u001b[1;32mc:\\Users\\soham\\anaconda3\\envs\\echodataflow\\lib\\site-packages\\prefect\\_internal\\concurrency\\api.py:243\u001b[0m, in \u001b[0;36mfrom_sync.wait_for_call_in_loop_thread\u001b[1;34m(_from_sync__call, timeout, done_callbacks, contexts)\u001b[0m\n\u001b[0;32m    241\u001b[0m     stack\u001b[38;5;241m.\u001b[39menter_context(context)\n\u001b[0;32m    242\u001b[0m waiter\u001b[38;5;241m.\u001b[39mwait()\n\u001b[1;32m--> 243\u001b[0m \u001b[38;5;28;01mreturn\u001b[39;00m \u001b[43mcall\u001b[49m\u001b[38;5;241;43m.\u001b[39;49m\u001b[43mresult\u001b[49m\u001b[43m(\u001b[49m\u001b[43m)\u001b[49m\n",
      "File \u001b[1;32mc:\\Users\\soham\\anaconda3\\envs\\echodataflow\\lib\\site-packages\\prefect\\_internal\\concurrency\\calls.py:284\u001b[0m, in \u001b[0;36mCall.result\u001b[1;34m(self, timeout)\u001b[0m\n\u001b[0;32m    278\u001b[0m \u001b[38;5;28;01mdef\u001b[39;00m \u001b[38;5;21mresult\u001b[39m(\u001b[38;5;28mself\u001b[39m, timeout: Optional[\u001b[38;5;28mfloat\u001b[39m] \u001b[38;5;241m=\u001b[39m \u001b[38;5;28;01mNone\u001b[39;00m) \u001b[38;5;241m-\u001b[39m\u001b[38;5;241m>\u001b[39m T:\n\u001b[0;32m    279\u001b[0m \u001b[38;5;250m    \u001b[39m\u001b[38;5;124;03m\"\"\"\u001b[39;00m\n\u001b[0;32m    280\u001b[0m \u001b[38;5;124;03m    Wait for the result of the call.\u001b[39;00m\n\u001b[0;32m    281\u001b[0m \n\u001b[0;32m    282\u001b[0m \u001b[38;5;124;03m    Not safe for use from asynchronous contexts.\u001b[39;00m\n\u001b[0;32m    283\u001b[0m \u001b[38;5;124;03m    \"\"\"\u001b[39;00m\n\u001b[1;32m--> 284\u001b[0m     \u001b[38;5;28;01mreturn\u001b[39;00m \u001b[38;5;28;43mself\u001b[39;49m\u001b[38;5;241;43m.\u001b[39;49m\u001b[43mfuture\u001b[49m\u001b[38;5;241;43m.\u001b[39;49m\u001b[43mresult\u001b[49m\u001b[43m(\u001b[49m\u001b[43mtimeout\u001b[49m\u001b[38;5;241;43m=\u001b[39;49m\u001b[43mtimeout\u001b[49m\u001b[43m)\u001b[49m\n",
      "File \u001b[1;32mc:\\Users\\soham\\anaconda3\\envs\\echodataflow\\lib\\site-packages\\prefect\\_internal\\concurrency\\calls.py:168\u001b[0m, in \u001b[0;36mFuture.result\u001b[1;34m(self, timeout)\u001b[0m\n\u001b[0;32m    166\u001b[0m     \u001b[38;5;28;01mraise\u001b[39;00m CancelledError()\n\u001b[0;32m    167\u001b[0m \u001b[38;5;28;01melif\u001b[39;00m \u001b[38;5;28mself\u001b[39m\u001b[38;5;241m.\u001b[39m_state \u001b[38;5;241m==\u001b[39m FINISHED:\n\u001b[1;32m--> 168\u001b[0m     \u001b[38;5;28;01mreturn\u001b[39;00m \u001b[38;5;28;43mself\u001b[39;49m\u001b[38;5;241;43m.\u001b[39;49m\u001b[43m__get_result\u001b[49m\u001b[43m(\u001b[49m\u001b[43m)\u001b[49m\n\u001b[0;32m    170\u001b[0m \u001b[38;5;28mself\u001b[39m\u001b[38;5;241m.\u001b[39m_condition\u001b[38;5;241m.\u001b[39mwait(timeout)\n\u001b[0;32m    172\u001b[0m \u001b[38;5;28;01mif\u001b[39;00m \u001b[38;5;28mself\u001b[39m\u001b[38;5;241m.\u001b[39m_state \u001b[38;5;129;01min\u001b[39;00m [CANCELLED, CANCELLED_AND_NOTIFIED]:\n\u001b[0;32m    173\u001b[0m     \u001b[38;5;66;03m# Raise Prefect cancelled error instead of\u001b[39;00m\n\u001b[0;32m    174\u001b[0m     \u001b[38;5;66;03m# `concurrent.futures._base.CancelledError`\u001b[39;00m\n",
      "File \u001b[1;32mc:\\Users\\soham\\anaconda3\\envs\\echodataflow\\lib\\concurrent\\futures\\_base.py:403\u001b[0m, in \u001b[0;36mFuture.__get_result\u001b[1;34m(self)\u001b[0m\n\u001b[0;32m    401\u001b[0m \u001b[38;5;28;01mif\u001b[39;00m \u001b[38;5;28mself\u001b[39m\u001b[38;5;241m.\u001b[39m_exception:\n\u001b[0;32m    402\u001b[0m     \u001b[38;5;28;01mtry\u001b[39;00m:\n\u001b[1;32m--> 403\u001b[0m         \u001b[38;5;28;01mraise\u001b[39;00m \u001b[38;5;28mself\u001b[39m\u001b[38;5;241m.\u001b[39m_exception\n\u001b[0;32m    404\u001b[0m     \u001b[38;5;28;01mfinally\u001b[39;00m:\n\u001b[0;32m    405\u001b[0m         \u001b[38;5;66;03m# Break a reference cycle with the exception in self._exception\u001b[39;00m\n\u001b[0;32m    406\u001b[0m         \u001b[38;5;28mself\u001b[39m \u001b[38;5;241m=\u001b[39m \u001b[38;5;28;01mNone\u001b[39;00m\n",
      "File \u001b[1;32mc:\\Users\\soham\\anaconda3\\envs\\echodataflow\\lib\\site-packages\\prefect\\_internal\\concurrency\\calls.py:355\u001b[0m, in \u001b[0;36mCall._run_async\u001b[1;34m(***failed resolving arguments***)\u001b[0m\n\u001b[0;32m    353\u001b[0m \u001b[38;5;28;01mwith\u001b[39;00m \u001b[38;5;28mself\u001b[39m\u001b[38;5;241m.\u001b[39mfuture\u001b[38;5;241m.\u001b[39menforce_async_deadline() \u001b[38;5;28;01mas\u001b[39;00m cancel_scope:\n\u001b[0;32m    354\u001b[0m     \u001b[38;5;28;01mtry\u001b[39;00m:\n\u001b[1;32m--> 355\u001b[0m         result \u001b[38;5;241m=\u001b[39m \u001b[38;5;28;01mawait\u001b[39;00m coro\n\u001b[0;32m    356\u001b[0m     \u001b[38;5;28;01mfinally\u001b[39;00m:\n\u001b[0;32m    357\u001b[0m         \u001b[38;5;66;03m# Forget this call's arguments in order to free up any memory\u001b[39;00m\n\u001b[0;32m    358\u001b[0m         \u001b[38;5;66;03m# that may be referenced by them; after a call has happened,\u001b[39;00m\n\u001b[0;32m    359\u001b[0m         \u001b[38;5;66;03m# there's no need to keep a reference to them\u001b[39;00m\n\u001b[0;32m    360\u001b[0m         \u001b[38;5;28mself\u001b[39m\u001b[38;5;241m.\u001b[39margs \u001b[38;5;241m=\u001b[39m \u001b[38;5;28;01mNone\u001b[39;00m\n",
      "File \u001b[1;32mc:\\Users\\soham\\anaconda3\\envs\\echodataflow\\lib\\site-packages\\prefect\\engine.py:1324\u001b[0m, in \u001b[0;36mget_task_call_return_value\u001b[1;34m(task, flow_run_context, parameters, wait_for, return_type, task_runner, extra_task_inputs)\u001b[0m\n\u001b[0;32m   1322\u001b[0m     \u001b[38;5;28;01mreturn\u001b[39;00m \u001b[38;5;28;01mawait\u001b[39;00m future\u001b[38;5;241m.\u001b[39m_wait()\n\u001b[0;32m   1323\u001b[0m \u001b[38;5;28;01melif\u001b[39;00m return_type \u001b[38;5;241m==\u001b[39m \u001b[38;5;124m\"\u001b[39m\u001b[38;5;124mresult\u001b[39m\u001b[38;5;124m\"\u001b[39m:\n\u001b[1;32m-> 1324\u001b[0m     \u001b[38;5;28;01mreturn\u001b[39;00m \u001b[38;5;28;01mawait\u001b[39;00m future\u001b[38;5;241m.\u001b[39m_result()\n\u001b[0;32m   1325\u001b[0m \u001b[38;5;28;01melse\u001b[39;00m:\n\u001b[0;32m   1326\u001b[0m     \u001b[38;5;28;01mraise\u001b[39;00m \u001b[38;5;167;01mValueError\u001b[39;00m(\u001b[38;5;124mf\u001b[39m\u001b[38;5;124m\"\u001b[39m\u001b[38;5;124mInvalid return type for task engine \u001b[39m\u001b[38;5;132;01m{\u001b[39;00mreturn_type\u001b[38;5;132;01m!r}\u001b[39;00m\u001b[38;5;124m.\u001b[39m\u001b[38;5;124m\"\u001b[39m)\n",
      "File \u001b[1;32mc:\\Users\\soham\\anaconda3\\envs\\echodataflow\\lib\\site-packages\\prefect\\futures.py:237\u001b[0m, in \u001b[0;36mPrefectFuture._result\u001b[1;34m(self, timeout, raise_on_failure)\u001b[0m\n\u001b[0;32m    235\u001b[0m \u001b[38;5;28;01mif\u001b[39;00m \u001b[38;5;129;01mnot\u001b[39;00m final_state:\n\u001b[0;32m    236\u001b[0m     \u001b[38;5;28;01mraise\u001b[39;00m \u001b[38;5;167;01mTimeoutError\u001b[39;00m(\u001b[38;5;124m\"\u001b[39m\u001b[38;5;124mCall timed out before task finished.\u001b[39m\u001b[38;5;124m\"\u001b[39m)\n\u001b[1;32m--> 237\u001b[0m \u001b[38;5;28;01mreturn\u001b[39;00m \u001b[38;5;28;01mawait\u001b[39;00m final_state\u001b[38;5;241m.\u001b[39mresult(raise_on_failure\u001b[38;5;241m=\u001b[39mraise_on_failure, fetch\u001b[38;5;241m=\u001b[39m\u001b[38;5;28;01mTrue\u001b[39;00m)\n",
      "File \u001b[1;32mc:\\Users\\soham\\anaconda3\\envs\\echodataflow\\lib\\site-packages\\prefect\\states.py:91\u001b[0m, in \u001b[0;36m_get_state_result\u001b[1;34m(state, raise_on_failure)\u001b[0m\n\u001b[0;32m     84\u001b[0m     \u001b[38;5;28;01mraise\u001b[39;00m UnfinishedRun(\n\u001b[0;32m     85\u001b[0m         \u001b[38;5;124mf\u001b[39m\u001b[38;5;124m\"\u001b[39m\u001b[38;5;124mRun is in \u001b[39m\u001b[38;5;132;01m{\u001b[39;00mstate\u001b[38;5;241m.\u001b[39mtype\u001b[38;5;241m.\u001b[39mname\u001b[38;5;132;01m}\u001b[39;00m\u001b[38;5;124m state, its result is not available.\u001b[39m\u001b[38;5;124m\"\u001b[39m\n\u001b[0;32m     86\u001b[0m     )\n\u001b[0;32m     88\u001b[0m \u001b[38;5;28;01mif\u001b[39;00m raise_on_failure \u001b[38;5;129;01mand\u001b[39;00m (\n\u001b[0;32m     89\u001b[0m     state\u001b[38;5;241m.\u001b[39mis_crashed() \u001b[38;5;129;01mor\u001b[39;00m state\u001b[38;5;241m.\u001b[39mis_failed() \u001b[38;5;129;01mor\u001b[39;00m state\u001b[38;5;241m.\u001b[39mis_cancelled()\n\u001b[0;32m     90\u001b[0m ):\n\u001b[1;32m---> 91\u001b[0m     \u001b[38;5;28;01mraise\u001b[39;00m \u001b[38;5;28;01mawait\u001b[39;00m get_state_exception(state)\n\u001b[0;32m     93\u001b[0m \u001b[38;5;28;01mif\u001b[39;00m \u001b[38;5;28misinstance\u001b[39m(state\u001b[38;5;241m.\u001b[39mdata, DataDocument):\n\u001b[0;32m     94\u001b[0m     result \u001b[38;5;241m=\u001b[39m result_from_state_with_data_document(\n\u001b[0;32m     95\u001b[0m         state, raise_on_failure\u001b[38;5;241m=\u001b[39mraise_on_failure\n\u001b[0;32m     96\u001b[0m     )\n",
      "File \u001b[1;32mc:\\Users\\soham\\anaconda3\\envs\\echodataflow\\lib\\site-packages\\prefect\\engine.py:1760\u001b[0m, in \u001b[0;36morchestrate_task_run\u001b[1;34m(task, task_run, parameters, wait_for, result_factory, log_prints, interruptible, client)\u001b[0m\n\u001b[0;32m   1753\u001b[0m         logger\u001b[38;5;241m.\u001b[39mdebug(\n\u001b[0;32m   1754\u001b[0m             \u001b[38;5;124m\"\u001b[39m\u001b[38;5;124mBeginning execution...\u001b[39m\u001b[38;5;124m\"\u001b[39m, extra\u001b[38;5;241m=\u001b[39m{\u001b[38;5;124m\"\u001b[39m\u001b[38;5;124mstate_message\u001b[39m\u001b[38;5;124m\"\u001b[39m: \u001b[38;5;28;01mTrue\u001b[39;00m}\n\u001b[0;32m   1755\u001b[0m         )\n\u001b[0;32m   1757\u001b[0m     call \u001b[38;5;241m=\u001b[39m from_async\u001b[38;5;241m.\u001b[39mcall_soon_in_new_thread(\n\u001b[0;32m   1758\u001b[0m         create_call(task\u001b[38;5;241m.\u001b[39mfn, \u001b[38;5;241m*\u001b[39margs, \u001b[38;5;241m*\u001b[39m\u001b[38;5;241m*\u001b[39mkwargs), timeout\u001b[38;5;241m=\u001b[39mtask\u001b[38;5;241m.\u001b[39mtimeout_seconds\n\u001b[0;32m   1759\u001b[0m     )\n\u001b[1;32m-> 1760\u001b[0m     result \u001b[38;5;241m=\u001b[39m \u001b[38;5;28;01mawait\u001b[39;00m call\u001b[38;5;241m.\u001b[39maresult()\n\u001b[0;32m   1762\u001b[0m \u001b[38;5;28;01mexcept\u001b[39;00m (CancelledError, asyncio\u001b[38;5;241m.\u001b[39mCancelledError) \u001b[38;5;28;01mas\u001b[39;00m exc:\n\u001b[0;32m   1763\u001b[0m     \u001b[38;5;28;01mif\u001b[39;00m \u001b[38;5;129;01mnot\u001b[39;00m call\u001b[38;5;241m.\u001b[39mtimedout():\n\u001b[0;32m   1764\u001b[0m         \u001b[38;5;66;03m# If the task call was not cancelled by us; this is a crash\u001b[39;00m\n",
      "File \u001b[1;32mc:\\Users\\soham\\anaconda3\\envs\\echodataflow\\lib\\site-packages\\prefect\\_internal\\concurrency\\calls.py:293\u001b[0m, in \u001b[0;36mCall.aresult\u001b[1;34m(self)\u001b[0m\n\u001b[0;32m    287\u001b[0m \u001b[38;5;250m\u001b[39m\u001b[38;5;124;03m\"\"\"\u001b[39;00m\n\u001b[0;32m    288\u001b[0m \u001b[38;5;124;03mWait for the result of the call.\u001b[39;00m\n\u001b[0;32m    289\u001b[0m \n\u001b[0;32m    290\u001b[0m \u001b[38;5;124;03mFor use from asynchronous contexts.\u001b[39;00m\n\u001b[0;32m    291\u001b[0m \u001b[38;5;124;03m\"\"\"\u001b[39;00m\n\u001b[0;32m    292\u001b[0m \u001b[38;5;28;01mtry\u001b[39;00m:\n\u001b[1;32m--> 293\u001b[0m     \u001b[38;5;28;01mreturn\u001b[39;00m \u001b[38;5;28;01mawait\u001b[39;00m asyncio\u001b[38;5;241m.\u001b[39mwrap_future(\u001b[38;5;28mself\u001b[39m\u001b[38;5;241m.\u001b[39mfuture)\n\u001b[0;32m    294\u001b[0m \u001b[38;5;28;01mexcept\u001b[39;00m asyncio\u001b[38;5;241m.\u001b[39mCancelledError \u001b[38;5;28;01mas\u001b[39;00m exc:\n\u001b[0;32m    295\u001b[0m     \u001b[38;5;28;01mraise\u001b[39;00m CancelledError() \u001b[38;5;28;01mfrom\u001b[39;00m \u001b[38;5;21;01mexc\u001b[39;00m\n",
      "File \u001b[1;32mc:\\Users\\soham\\anaconda3\\envs\\echodataflow\\lib\\asyncio\\futures.py:285\u001b[0m, in \u001b[0;36mFuture.__await__\u001b[1;34m(self)\u001b[0m\n\u001b[0;32m    283\u001b[0m \u001b[38;5;28;01mif\u001b[39;00m \u001b[38;5;129;01mnot\u001b[39;00m \u001b[38;5;28mself\u001b[39m\u001b[38;5;241m.\u001b[39mdone():\n\u001b[0;32m    284\u001b[0m     \u001b[38;5;28mself\u001b[39m\u001b[38;5;241m.\u001b[39m_asyncio_future_blocking \u001b[38;5;241m=\u001b[39m \u001b[38;5;28;01mTrue\u001b[39;00m\n\u001b[1;32m--> 285\u001b[0m     \u001b[38;5;28;01myield\u001b[39;00m \u001b[38;5;28mself\u001b[39m  \u001b[38;5;66;03m# This tells Task to wait for completion.\u001b[39;00m\n\u001b[0;32m    286\u001b[0m \u001b[38;5;28;01mif\u001b[39;00m \u001b[38;5;129;01mnot\u001b[39;00m \u001b[38;5;28mself\u001b[39m\u001b[38;5;241m.\u001b[39mdone():\n\u001b[0;32m    287\u001b[0m     \u001b[38;5;28;01mraise\u001b[39;00m \u001b[38;5;167;01mRuntimeError\u001b[39;00m(\u001b[38;5;124m\"\u001b[39m\u001b[38;5;124mawait wasn\u001b[39m\u001b[38;5;124m'\u001b[39m\u001b[38;5;124mt used with future\u001b[39m\u001b[38;5;124m\"\u001b[39m)\n",
      "File \u001b[1;32mc:\\Users\\soham\\anaconda3\\envs\\echodataflow\\lib\\asyncio\\tasks.py:304\u001b[0m, in \u001b[0;36mTask.__wakeup\u001b[1;34m(self, future)\u001b[0m\n\u001b[0;32m    302\u001b[0m \u001b[38;5;28;01mdef\u001b[39;00m \u001b[38;5;21m__wakeup\u001b[39m(\u001b[38;5;28mself\u001b[39m, future):\n\u001b[0;32m    303\u001b[0m     \u001b[38;5;28;01mtry\u001b[39;00m:\n\u001b[1;32m--> 304\u001b[0m         \u001b[43mfuture\u001b[49m\u001b[38;5;241;43m.\u001b[39;49m\u001b[43mresult\u001b[49m\u001b[43m(\u001b[49m\u001b[43m)\u001b[49m\n\u001b[0;32m    305\u001b[0m     \u001b[38;5;28;01mexcept\u001b[39;00m \u001b[38;5;167;01mBaseException\u001b[39;00m \u001b[38;5;28;01mas\u001b[39;00m exc:\n\u001b[0;32m    306\u001b[0m         \u001b[38;5;66;03m# This may also be a cancellation.\u001b[39;00m\n\u001b[0;32m    307\u001b[0m         \u001b[38;5;28mself\u001b[39m\u001b[38;5;241m.\u001b[39m__step(exc)\n",
      "File \u001b[1;32mc:\\Users\\soham\\anaconda3\\envs\\echodataflow\\lib\\asyncio\\futures.py:201\u001b[0m, in \u001b[0;36mFuture.result\u001b[1;34m(self)\u001b[0m\n\u001b[0;32m    199\u001b[0m \u001b[38;5;28mself\u001b[39m\u001b[38;5;241m.\u001b[39m__log_traceback \u001b[38;5;241m=\u001b[39m \u001b[38;5;28;01mFalse\u001b[39;00m\n\u001b[0;32m    200\u001b[0m \u001b[38;5;28;01mif\u001b[39;00m \u001b[38;5;28mself\u001b[39m\u001b[38;5;241m.\u001b[39m_exception \u001b[38;5;129;01mis\u001b[39;00m \u001b[38;5;129;01mnot\u001b[39;00m \u001b[38;5;28;01mNone\u001b[39;00m:\n\u001b[1;32m--> 201\u001b[0m     \u001b[38;5;28;01mraise\u001b[39;00m \u001b[38;5;28mself\u001b[39m\u001b[38;5;241m.\u001b[39m_exception\u001b[38;5;241m.\u001b[39mwith_traceback(\u001b[38;5;28mself\u001b[39m\u001b[38;5;241m.\u001b[39m_exception_tb)\n\u001b[0;32m    202\u001b[0m \u001b[38;5;28;01mreturn\u001b[39;00m \u001b[38;5;28mself\u001b[39m\u001b[38;5;241m.\u001b[39m_result\n",
      "File \u001b[1;32mc:\\Users\\soham\\anaconda3\\envs\\echodataflow\\lib\\site-packages\\prefect\\_internal\\concurrency\\calls.py:318\u001b[0m, in \u001b[0;36mCall._run_sync\u001b[1;34m(***failed resolving arguments***)\u001b[0m\n\u001b[0;32m    316\u001b[0m \u001b[38;5;28;01mwith\u001b[39;00m \u001b[38;5;28mself\u001b[39m\u001b[38;5;241m.\u001b[39mfuture\u001b[38;5;241m.\u001b[39menforce_sync_deadline() \u001b[38;5;28;01mas\u001b[39;00m cancel_scope:\n\u001b[0;32m    317\u001b[0m     \u001b[38;5;28;01mtry\u001b[39;00m:\n\u001b[1;32m--> 318\u001b[0m         result \u001b[38;5;241m=\u001b[39m \u001b[38;5;28mself\u001b[39m\u001b[38;5;241m.\u001b[39mfn(\u001b[38;5;241m*\u001b[39m\u001b[38;5;28mself\u001b[39m\u001b[38;5;241m.\u001b[39margs, \u001b[38;5;241m*\u001b[39m\u001b[38;5;241m*\u001b[39m\u001b[38;5;28mself\u001b[39m\u001b[38;5;241m.\u001b[39mkwargs)\n\u001b[0;32m    319\u001b[0m     \u001b[38;5;28;01mfinally\u001b[39;00m:\n\u001b[0;32m    320\u001b[0m         \u001b[38;5;66;03m# Forget this call's arguments in order to free up any memory\u001b[39;00m\n\u001b[0;32m    321\u001b[0m         \u001b[38;5;66;03m# that may be referenced by them; after a call has happened,\u001b[39;00m\n\u001b[0;32m    322\u001b[0m         \u001b[38;5;66;03m# there's no need to keep a reference to them\u001b[39;00m\n\u001b[0;32m    323\u001b[0m         \u001b[38;5;28mself\u001b[39m\u001b[38;5;241m.\u001b[39margs \u001b[38;5;241m=\u001b[39m \u001b[38;5;28;01mNone\u001b[39;00m\n",
      "File \u001b[1;32mc:\\Users\\soham\\anaconda3\\envs\\echodataflow\\lib\\site-packages\\echodataflow\\aspects\\echodataflow_aspect.py:97\u001b[0m, in \u001b[0;36mechodataflow.<locals>.decorator.<locals>.wrapper\u001b[1;34m(*args, **kwargs)\u001b[0m\n\u001b[0;32m     95\u001b[0m     \u001b[38;5;28;01mreturn\u001b[39;00m {\u001b[38;5;124m'\u001b[39m\u001b[38;5;124merror\u001b[39m\u001b[38;5;124m'\u001b[39m: \u001b[38;5;28;01mTrue\u001b[39;00m, \u001b[38;5;124m'\u001b[39m\u001b[38;5;124merror_desc\u001b[39m\u001b[38;5;124m'\u001b[39m: e}\n\u001b[0;32m     96\u001b[0m \u001b[38;5;28;01melse\u001b[39;00m:\n\u001b[1;32m---> 97\u001b[0m     \u001b[38;5;28;01mraise\u001b[39;00m e\n",
      "File \u001b[1;32mc:\\Users\\soham\\anaconda3\\envs\\echodataflow\\lib\\site-packages\\echodataflow\\aspects\\echodataflow_aspect.py:90\u001b[0m, in \u001b[0;36mechodataflow.<locals>.decorator.<locals>.wrapper\u001b[1;34m(*args, **kwargs)\u001b[0m\n\u001b[0;32m     87\u001b[0m \u001b[38;5;28;01mtry\u001b[39;00m:\n\u001b[0;32m     88\u001b[0m     before_function_call(\n\u001b[0;32m     89\u001b[0m         gea, \u001b[38;5;28mtype\u001b[39m, processing_stage, \u001b[38;5;241m*\u001b[39margs, \u001b[38;5;241m*\u001b[39m\u001b[38;5;241m*\u001b[39mkwargs)\n\u001b[1;32m---> 90\u001b[0m     result \u001b[38;5;241m=\u001b[39m func(\u001b[38;5;241m*\u001b[39margs, \u001b[38;5;241m*\u001b[39m\u001b[38;5;241m*\u001b[39mkwargs)\n\u001b[0;32m     91\u001b[0m     after_function_call(gea, \u001b[38;5;241m*\u001b[39margs, \u001b[38;5;241m*\u001b[39m\u001b[38;5;241m*\u001b[39mkwargs)\n\u001b[0;32m     92\u001b[0m     \u001b[38;5;28;01mreturn\u001b[39;00m result\n",
      "File \u001b[1;32mc:\\Users\\soham\\anaconda3\\envs\\echodataflow\\lib\\site-packages\\echodataflow\\utils\\config_utils.py:440\u001b[0m, in \u001b[0;36mclub_raw_files\u001b[1;34m(config, raw_dicts, raw_url_file, json_storage_options)\u001b[0m\n\u001b[0;32m    438\u001b[0m \u001b[38;5;28;01mif\u001b[39;00m \u001b[38;5;28mlen\u001b[39m(raw_dicts) \u001b[38;5;241m==\u001b[39m \u001b[38;5;241m0\u001b[39m:\n\u001b[0;32m    439\u001b[0m     \u001b[38;5;28;01mif\u001b[39;00m raw_url_file \u001b[38;5;129;01mis\u001b[39;00m \u001b[38;5;28;01mNone\u001b[39;00m:\n\u001b[1;32m--> 440\u001b[0m         \u001b[38;5;28;01mraise\u001b[39;00m \u001b[38;5;167;01mValueError\u001b[39;00m(\u001b[38;5;124m\"\u001b[39m\u001b[38;5;124mMust have raw_dicts or raw_json_path present.\u001b[39m\u001b[38;5;124m\"\u001b[39m)\n\u001b[0;32m    441\u001b[0m     file_system \u001b[38;5;241m=\u001b[39m extract_fs(\n\u001b[0;32m    442\u001b[0m         raw_url_file, storage_options\u001b[38;5;241m=\u001b[39mjson_storage_options\n\u001b[0;32m    443\u001b[0m     )\n\u001b[0;32m    444\u001b[0m     \u001b[38;5;28;01mwith\u001b[39;00m file_system\u001b[38;5;241m.\u001b[39mopen(raw_url_file) \u001b[38;5;28;01mas\u001b[39;00m f:\n",
      "\u001b[1;31mValueError\u001b[0m: Must have raw_dicts or raw_json_path present."
     ]
    }
   ],
   "source": [
    "options = {\"storage_options_override\": False}\n",
    "data  = echodataflow_start(dataset_config=dataset_config, pipeline_config=pipeline_config, options=options)"
   ]
  },
  {
   "cell_type": "markdown",
   "metadata": {},
   "source": [
    "## Step 5: Results\n",
    "Finally, let's take a look at the first entry from the processed data."
   ]
  },
  {
   "cell_type": "code",
   "execution_count": null,
   "metadata": {},
   "outputs": [],
   "source": [
    "data[0][0]"
   ]
  },
  {
   "cell_type": "markdown",
   "metadata": {},
   "source": [
    "**Congratulations!** You've successfully processed EK60 data using echodataflow. This notebook provides a simplified overview, and you can explore the capabilities of echodataflow for more advanced processing tasks.\n",
    "\n",
    "Feel free to modify the parameters, paths, and configurations as needed to adapt to your data and requirements."
   ]
  },
  {
   "cell_type": "code",
   "execution_count": null,
   "metadata": {},
   "outputs": [],
   "source": []
  }
 ],
 "metadata": {
  "kernelspec": {
   "display_name": "Python 3 (ipykernel)",
   "language": "python",
   "name": "python3"
  },
  "language_info": {
   "codemirror_mode": {
    "name": "ipython",
    "version": 3
   },
   "file_extension": ".py",
   "mimetype": "text/x-python",
   "name": "python",
   "nbconvert_exporter": "python",
   "pygments_lexer": "ipython3",
   "version": "3.10.13"
  }
 },
 "nbformat": 4,
 "nbformat_minor": 4
}
